Workbook

Sheet 機器設備
A1: 設備分類 | B1: 機器名稱 | C1: 需要的小妖精(個) | D1: 運轉電力(FV/s) | E1: 支援液體種類 | F1: 持續液體流率(fl/s) | G1: 基礎流率/能力 | H1: 特殊機制說明
A2: 必備機器 | B2: 虛空熔爐 | C2: 1 | D2: 0 | E2: 無 | F2: 無 | G2: 4 FV/s (常規) / 16 FV/s (汙泥增效) | H2: 供給機器運轉；燃燒煤炭(0.1/s)常規發電 4 FV/s；每10秒多消耗1個虛空汙泥(0.1/s)可提升發電量至 16 FV/s。
A3: 必備機器 | B3: 分撿機 | C3: 0 | D3: 1 | E3: 無 | F3: 無 | G3: - | H3: 負責將物品/食材分類、送往不同方向
A4: 必備機器 | B4: 裝配機 | C4: 0 | D4: 1 | E4: 無 | F4: 無 | G4: - | H4: 用於傳輸物品/液體/電力等
A5: 必備機器 | B5: 送餐大炮 | C5: 0 | D5: 1 | E5: 無 | F5: 無 | G5: - | H5: 將料理發射給怪獸
A6: 必備機器 | B6: 儲物箱 | C6: 0 | D6: 0 | E6: 無 | F6: 無 | G6: - | H6: 15格儲存空間，每格最高堆疊999個
A7: 必備機器 | B7: 分流器 | C7: 0 | D7: 1 | E7: 無 | F7: 無 | G7: - | H7: 設定不同輸出口的輸出物配比，形成分流
A8: 收割機器 | B8: 採掘機 | C8: 1 | D8: 1 | E8: 無 | F8: 無 | G8: 0.2 個/秒 | H8: 遊戲中一格礦石可無限開採不會枯竭
A9: 收割機器 | B9: 虛空泵機 | C9: 1 | D9: 1 | E9: 水 / 虛空 / 油 / 醬汁 | F9: 0 (產出端) | G9: 2 fl/s (常規) / 8 fl/s (汙泥增效) | H9: 一格液體無限抽取；每5秒消耗1個虛空汙泥可提速至 8 fl/s。
A10: 收割機器 | B10: 收割機 | C10: 1 | D10: 1 | E10: 無 | F10: 無 | G10: 0.2 個/秒 | H10: 植物節點無限採收；可用槌子敲起植物移植至指定生長方塊上
A11: 轉化機器 | B11: 發酵罐 | C11: 2 | D11: 1 | E11: 指定發酵液 | F11: 1(發酵液) | G11: 10秒5個 (0.5/s) | H11: 不同物品需要對應不同液體進行發酵
A12: 轉化機器 | B12: 油炸鍋 | C12: 2 | D12: 1 | E12: 油 | F12: 1 (油) | G12: 5秒1個 (0.2/s)
A13: 轉化機器 | B13: 注入機 | C13: 2 | D13: 1 | E13: 無 | F13: 無 | G13: - | H13: 轉化機器；放置於液體中（如油池），每5秒輸入1個辛香料，將相連液體原位轉化為目標液體（如炙烈紅油）；轉化後需藉由泵機抽取輸送。運轉電力 1 FV/s，打工小妖精 2 個。
A14: 轉化機器 | B14: 物質操縱機 | C14: 1 | D14: 1 | E14: 虛空 | F14: 1(虛空) | G14: 5秒1個 (0.2/s) / 5秒2個 (0.4/s) | H14: 消耗任意固體物品x1與虛空1 fl/s重構；一般為5秒1個，泥沼蟑螂為5秒2個；未設配方或缺料時自動產出虛空汙泥。
A15: 轉化機器 | B15: 烤箱 | C15: 1 | D15: 1 | E15: 無 | F15: 無 | G15: 0.2 個/秒 | H15: 冶煉製程/燒製製程/烘焙製程
A16: 轉化機器 | B16: 煮鍋 | C16: 2 | D16: 1 | E16: 水 | F16: 1 (水) | G16: 5秒1個 (0.2/s) | H16: 水煮熟化
A17: 加工機器 | B17: 混合機 | C17: 2 | D17: 1 | E17: 依配方需求 (水/指定液體或無) | F17: 0.5 (需要時) / 0 (無) | G17: 4秒1個 (0.25/s) / 4秒2個 (0.5/s) / 4秒3個 (0.75/s) | H17: 依配方決定是否通入液體，每 4 秒週期消耗 2 fl 液體（持續流率 0.5 fl/s）；產出效率分 4 秒 1 個、4 秒 2 個或 4 秒 3 個 (0.75/s)。
A18: 加工機器 | B18: 自動廚師機 | C18: 3 | D18: 1 | E18: 依配方需求 (指定液體或無) | F18: 1 (需要時) / 0 (無) | G18: 5秒1個 (0.2/s) | H18: 固體食材配比恆為 1:1；液體依配方需求(固定 1 fl/s)或無；專門產出可餵食怪獸之完成品料理。
A19: 加工機器 | B19: 擠出機 | C19: 2 | D19: 1 | E19: 無 | F19: 無 | G19: 0.25 個/秒 | H19: 消耗固體原料擠出成型
A20: 加工機器 | B20: 研磨機 | C20: 2 | D20: 1 | E20: 無 | F20: 無 | G20: 1 個/秒 | H20: 將食物或物品磨成粉
A21: 加工機器 | B21: 攪拌機 | C21: 2 | D21: 1 | E21: 無 | F21: 無 | G21: 1 fl/s | H21: 消耗食材持續產出醬汁

Sheet 中間配方
A1: 產物名稱 | B1: 加工設備 | C1: 所需液體種類 | D1: 持續液體流量(fl/s) | E1: 固體原料1名稱 | F1: 固體原料1數量 | G1: 固體原料2名稱 | H1: 固體原料2數量 | I1: 固體原料3名稱 | J1: 固體原料3數量 | K1: 固體原料4名稱 | L1: 固體原料4數量 | M1: 週期時間(秒) | N1: 單次產量(個) | O1: 基礎產出速率(個/秒) | P1: 備註/特殊機制
A2: 物品管道 | B2: 裝配機 | C2: 無 | D2: 0 | E2: 鐵 | F2: 1 | G2: 玻璃 | H2: 1 | I2: 無 | J2: 0 | K2: 無 | L2: 0 | M2: 5 | N2: 8 | O2: =N2/M2 -> 1.6 | P2: 用於傳輸物品
A3: 液體管道 | B3: 裝配機 | C3: 無 | D3: 0 | E3: 橡膠 | F3: 1 | G3: 玻璃 | H3: 1 | I3: 無 | J3: 0 | K3: 無 | L3: 0 | M3: 5 | N3: 8 | O3: =N3/M3 -> 1.6 | P3: 用於傳輸液體
A4: 電線 | B4: 裝配機 | C4: 無 | D4: 0 | E4: 鐵 | F4: 1 | G4: 橡膠 | H4: 1 | I4: 無 | J4: 0 | K4: 無 | L4: 0 | M4: 5 | N4: 8 | O4: =N4/M4 -> 1.6 | P4: 用於傳輸電力
A5: 梯子 | B5: 裝配機 | C5: 無 | D5: 0 | E5: 鐵 | F5: 1 | G5: 煤炭 | H5: 1 | I5: 無 | J5: 0 | K5: 無 | L5: 0 | M5: 5 | N5: 8 | O5: =N5/M5 -> 1.6 | P5: 用於攀爬
A6: 腳手架 | B6: 裝配機 | C6: 無 | D6: 0 | E6: 鐵 | F6: 1 | G6: 煤炭 | H6: 1 | I6: 無 | J6: 0 | K6: 無 | L6: 0 | M6: 5 | N6: 8 | O6: =N6/M6 -> 1.6 | P6: 作為實體方塊使用
A7: 平台 | B7: 裝配機 | C7: 無 | D7: 0 | E7: 鐵 | F7: 1 | G7: 煤炭 | H7: 1 | I7: 無 | J7: 0 | K7: 無 | L7: 0 | M7: 5 | N7: 8 | O7: =N7/M7 -> 1.6 | P7: 可從頂部往下穿的實體
A8: 彈簧板 | B8: 裝配機 | C8: 無 | D8: 0 | E8: 鐵 | F8: 1 | G8: 橡膠 | H8: 1 | I8: 無 | J8: 0 | K8: 無 | L8: 0 | M8: 5 | N8: 8 | O8: =N8/M8 -> 1.6 | P8: 使角色彈跳更高
A9: 傳送帶 | B9: 裝配機 | C9: 無 | D9: 0 | E9: 鐵 | F9: 1 | G9: 橡膠 | H9: 1 | I9: 無 | J9: 0 | K9: 無 | L9: 0 | M9: 5 | N9: 8 | O9: =N9/M9 -> 1.6 | P9: 水平傳輸物品
A10: 綠色史萊姆 | B10: 物質操縱機 | C10: 虛空 | D10: 1 | E10: 任意物品 | F10: 1 | I10: 無 | J10: 0 | K10: 無 | L10: 0 | M10: 5 | N10: 1 | O10: =N10/M10 -> 0.2 | P10: 消耗任意物品與虛空等價轉換
A11: 巫妖骸骨 | B11: 物質操縱機 | C11: 虛空 | D11: 1 | E11: 任意物品 | F11: 1 | I11: 無 | J11: 0 | K11: 無 | L11: 0 | M11: 5 | N11: 1 | O11: =N11/M11 -> 0.2 | P11: 消耗任意物品與虛空等價轉換
A12: 蜘蛛蛋 | B12: 物質操縱機 | C12: 虛空 | D12: 1 | E12: 任意物品 | F12: 1 | I12: 無 | J12: 0 | K12: 無 | L12: 0 | M12: 5 | N12: 1 | O12: =N12/M12 -> 0.2 | P12: 消耗任意物品與虛空等價轉換
A13: 蛇蛋 | B13: 物質操縱機 | C13: 虛空 | D13: 1 | E13: 任意物品 | F13: 1 | I13: 無 | J13: 0 | K13: 無 | L13: 0 | M13: 5 | N13: 1 | O13: =N13/M13 -> 0.2 | P13: 消耗任意物品與虛空等價轉換
A14: 泥沼蟑螂 | B14: 物質操縱機 | C14: 虛空 | D14: 1 | E14: 任意物品 | F14: 1 | I14: 無 | J14: 0 | K14: 無 | L14: 0 | M14: 5 | N14: 2 | O14: =N14/M14 -> 0.4 | P14: 特殊雙倍產量配方
A15: 虛空汙泥 | B15: 物質操縱機 | C15: 虛空 | D15: 1 | E15: 無(空載) | F15: 0 | I15: 無 | J15: 0 | K15: 無 | L15: 0 | M15: 5 | N15: 1 | O15: =N15/M15 -> 0.2 | P15: 未輸入物品或未設定產物時自動凝結
A16: 鐵 | B16: 烤箱 | C16: 無 | D16: 0 | E16: 鐵礦石 | F16: 1 | I16: 無 | J16: 0 | K16: 無 | L16: 0 | M16: 5 | N16: 1 | O16: =N16/M16 -> 0.2 | P16: 冶煉製程
A17: 玻璃 | B17: 烤箱 | C17: 無 | D17: 0 | E17: 沙塊 | F17: 1 | I17: 無 | J17: 0 | K17: 無 | L17: 0 | M17: 5 | N17: 1 | O17: =N17/M17 -> 0.2 | P17: 燒製製程
A18: 麵包 | B18: 烤箱 | C18: 無 | D18: 0 | E18: 發酵麵糰 | F18: 1 | I18: 無 | J18: 0 | K18: 無 | L18: 0 | M18: 5 | N18: 1 | O18: =N18/M18 -> 0.2 | P18: 烘焙製程
A19: 煮熟的通心粉 | B19: 煮鍋 | C19: 水 | D19: 1 | E19: 生通心粉 | F19: 1 | I19: 無 | J19: 0 | K19: 無 | L19: 0 | M19: 5 | N19: 1 | O19: =N19/M19 -> 0.2 | P19: 水煮熟化
A20: 煮熟的千層麵皮 | B20: 煮鍋 | C20: 水 | D20: 1 | E20: 生千層麵 | F20: 1 | I20: 無 | J20: 0 | K20: 無 | L20: 0 | M20: 5 | N20: 1 | O20: =N20/M20 -> 0.2 | P20: 水煮熟化
A21: 煮熟的義大利麵 | B21: 煮鍋 | C21: 水 | D21: 1 | E21: 生義大利麵 | F21: 1 | I21: 無 | J21: 0 | K21: 無 | L21: 0 | M21: 5 | N21: 1 | O21: =N21/M21 -> 0.2 | P21: 水煮熟化
A22: 塔瑪茄醬 | B22: 攪拌機 | C22: 無 | D22: 0 | E22: 塔瑪茄 | F22: 1 | G22: 日桂葉 | H22: 1 | I22: 無 | J22: 0 | K22: 無 | L22: 0 | M22: 5 | N22: 5 | O22: =N22/M22 -> 1 | P22: 每5秒消耗塔瑪茄x1與日桂葉x1，持續產出塔瑪茄醬液體
A23: 骨粉 | B23: 研磨機 | C23: 無 | D23: 0 | E23: 巫妖骸骨 | F23: 1 | I23: 無 | J23: 0 | K23: 無 | L23: 0 | M23: 2 | N23: 2 | O23: =N23/M23 -> 1 | P23: 將1個巫妖骸骨研磨成2個骨粉
A24: 義大利麵團 | B24: 混合機 | C24: 無 | D24: 0 | E24: 骨粉 | F24: 1 | G24: 蜘蛛蛋 | H24: 1 | I24: 無 | J24: 0 | K24: 無 | L24: 0 | M24: 4 | N24: 1 | O24: =N24/M24 -> 0.25 | P24: 骨粉x1與蜘蛛蛋x1混合成義大利麵團
A25: 生通心粉 | B25: 擠出機 | C25: 無 | D25: 0 | E25: 義大利麵團 | F25: 1 | I25: 無 | J25: 0 | K25: 無 | L25: 0 | M25: 4 | N25: 1 | O25: =N25/M25 -> 0.25 | P25: 將義大利麵團擠出成型為生通心粉
A26: 生千層麵 | B26: 擠出機 | C26: 無 | D26: 0 | E26: 義大利麵團 | F26: 1 | I26: 無 | J26: 0 | K26: 無 | L26: 0 | M26: 4 | N26: 1 | O26: =N26/M26 -> 0.25 | P26: 將義大利麵團擠出成型為生千層麵皮
A27: 史萊姆肉餡 | B27: 研磨機 | C27: 無 | D27: 0 | E27: 綠色史萊姆 | F27: 1 | I27: 無 | J27: 0 | K27: 無 | L27: 0 | M27: 2 | N27: 2 | O27: =N27/M27 -> 1 | P27: 將1個綠色史萊姆絞碎成2個史萊姆肉餡
A28: 塔瑪茄 | B28: 收割機 | C28: 無 | D28: 0 | E28: 塔瑪茄植株 | F28: 1 | I28: 無 | J28: 0 | K28: 無 | L28: 0 | M28: 5 | N28: 1 | O28: =N28/M28 -> 0.2 | P28: 收割機採收自然生長之塔瑪茄
A29: 日桂葉 | B29: 收割機 | C29: 無 | D29: 0 | E29: 日桂葉植株 | F29: 1 | I29: 無 | J29: 0 | K29: 無 | L29: 0 | M29: 5 | N29: 1 | O29: =N29/M29 -> 0.2 | P29: 收割機採收生長於石頭之日桂葉
A30: 豆肉蔻 | B30: 採掘機 | C30: 無 | D30: 0 | E30: 豆肉蔻(礦石方塊) | F30: 1 | I30: 無 | J30: 0 | K30: 無 | L30: 0 | M30: 5 | N30: 1 | O30: =N30/M30 -> 0.2 | P30: 採掘機開採香料礦石，具過敏原特性
A31: 鹽 | B31: 採掘機 | C31: 無 | D31: 0 | E31: 鹽(礦石方塊) | F31: 1 | I31: 無 | J31: 0 | K31: 無 | L31: 0 | M31: 5 | N31: 1 | O31: =N31/M31 -> 0.2 | P31: 採掘機開採鹽礦石
A32: 生史萊姆肉丸 | B32: 混合機 | C32: 無 | D32: 0 | E32: 綠色史萊姆 | F32: 1 | G32: 豆肉蔻 | H32: 1 | I32: 無 | J32: 0 | K32: 無 | L32: 0 | M32: 4 | N32: 1 | O32: =N32/M32 -> 0.25 | P32: 綠色史萊姆與豆肉蔻混和製成生肉丸
A33: 炸史萊姆肉丸 | B33: 油炸鍋 | C33: 油 | D33: 1 | E33: 生史萊姆肉丸 | F33: 1 | G33: 無 | H33: 0 | I33: 無 | J33: 0 | K33: 無 | L33: 0 | M33: 5 | N33: 1 | O33: =N33/M33 -> 0.2 | P33: 在油中炸成炸史萊姆肉丸
A34: 炒蜘蛛蛋 | B34: 混合機 | C34: 無 | D34: 0 | E34: 蜘蛛蛋 | F34: 1 | G34: 鹽 | H34: 1 | I34: 無 | J34: 0 | K34: 無 | L34: 0 | M34: 4 | N34: 1 | O34: =N34/M34 -> 0.25 | P34: 蜘蛛蛋與鹽混和製成炒蜘蛛蛋
A35: 青醬 | B35: 攪拌機 | C35: 無 | D35: 0 | E35: 日桂葉 | F35: 1 | G35: 豆肉蔻 | H35: 1 | I35: 無 | J35: 0 | K35: 無 | L35: 0 | M35: 5 | N35: 5 | O35: =N35/M35 -> 1 | P35: 日桂葉x1與豆肉蔻x1於攪拌機攪打成青醬
A36: 炸蜘蛛蛋 | B36: 油炸鍋 | C36: 油 | D36: 1 | E36: 蜘蛛蛋 | F36: 1 | G36: 無 | H36: 0 | I36: 無 | J36: 0 | K36: 無 | L36: 0 | M36: 5 | N36: 1 | O36: =N36/M36 -> 0.2 | P36: 在油中炸成炸蜘蛛蛋
A37: 塔瑪茄泥 | B37: 混合機 | C37: 無 | D37: 0 | E37: 塔瑪茄 | F37: 1 | G37: 豆肉蔻 | H37: 1 | I37: 無 | J37: 0 | K37: 無 | L37: 0 | M37: 4 | N37: 1 | O37: =N37/M37 -> 0.25 | P37: 塔瑪茄與豆肉蔻混和製成
A38: 生玉米餅 | B38: 混合機 | C38: 油 | D38: 0.5 | E38: 骨粉 | F38: 1 | G38: 無 | H38: 0 | I38: 無 | J38: 0 | K38: 無 | L38: 0 | M38: 4 | N38: 2 | O38: =N38/M38 -> 0.5 | P38: 骨粉與油混和製成生玉米餅(雙倍產量)
A39: 玉米餅 | B39: 烤箱 | C39: 無 | D39: 0 | E39: 生玉米餅 | F39: 1 | G39: 無 | H39: 0 | I39: 無 | J39: 0 | K39: 無 | L39: 0 | M39: 5 | N39: 1 | O39: =N39/M39 -> 0.2 | P39: 烘烤成玉米餅
A40: 多林多滋 | B40: 油炸鍋 | C40: 油 | D40: 1 | E40: 玉米餅 | F40: 1 | G40: 無 | H40: 0 | I40: 無 | J40: 0 | K40: 無 | L40: 0 | M40: 5 | N40: 1 | O40: =N40/M40 -> 0.2 | P40: 在油中炸成多林多滋脆片
...

Sheet 食材&物品
A1: 所屬分類/島嶼 | B1: 食材/物品名稱 | C1: 取得或加工途徑 | D1: 是否會腐壞/發酵 | E1: 腐壞時間(秒) | F1: 腐壞後轉化產物 | G1: 特殊屬性(過敏原/遇熱凝固/發酵膨脹/感染性) | H1: 說明備註
A2: 常規物資 | B2: 煤炭 | C2: 採掘機 | D2: 否 | E2: - | H2: 燃燒發電
A3: 常規物資 | B3: 物品管道 | C3: 裝配機 | D3: 否 | E3: - | H3: 用於傳輸物品
A4: 常規物資 | B4: 液體管道 | C4: 裝配機 | D4: 否 | E4: - | H4: 用於傳輸液體
A5: 常規物資 | B5: 電線 | C5: 裝配機 | D5: 否 | E5: - | H5: 用於傳輸電力
A6: 常規物資 | B6: 梯子 | C6: 裝配機 | D6: 否 | E6: - | H6: 用於攀爬
A7: 常規物資 | B7: 腳手架 | C7: 裝配機 | D7: 否 | E7: - | H7: 作為實體方塊使用；可放置於液體表面
A8: 常規物資 | B8: 平台 | C8: 裝配機 | D8: 否 | E8: - | H8: 可從頂部往下穿的實體(按方向鍵即可穿透)；可放置於液體表面
A9: 常規物資 | B9: 鬼魅菇 | C9: 地圖生成 | D9: 否 | E9: - | H9: 生長於石頭
A10: 常規物資 | B10: 鬼魅菇孢子 | C10: 收割機 | D10: 否 | E10: - | H10: 合成打工小妖精材料
A11: 常規物資 | B11: 傳送帶 | C11: 裝配機 | D11: 否 | E11: - | H11: 輸送物品/食材
A12: 常規物資 | B12: 彈簧板 | C12: 裝配機 | D12: 否 | E12: - | H12: 使角色彈跳更高
A13: 常規物資 | B13: 發酵好的打工小妖精 | C13: 烤箱 | D13: 否 | E13: - | H13: 建造機器用
... A20: 常規物資 | B20: 橡膠 | C20: 烤箱 | D20: 否 | E20: - | H20: 合成用
A21: 常規物資 | B21: 黏土 | C21: 採掘機 | D21: 否 | E21: -
A22: 常規物資 | B22: 哥布林肉排 | C22: 角色死亡 | D22: 否 | E22: - | G22: 食物中毒 | H22: 烤箱放入不支持物品時產生
A23: 常規物資 | B23: 灰燼 | C23: 烤箱 | D23: 否 | E23: - | H23: 將無法燒的物品放入烤箱形成
A24: 常規物資 | B24: 粉塵 | C24: 研磨機 | D24: 否 | E24: - | H24: 將除巫妖骸骨外的物品放入研磨機形成，用於合成麵團
A25: 常規物資 | B25: 虛空汙泥 | C25: 物質操縱機 | D25: 否 | E25: - | G25: 氣味刺鼻 | H25: 物質操縱機通電通虛空但未輸入物品或未設定產物時產出；可作為虛空泵機超頻燃料（每5秒消耗1個，流量提速至8 fl/s）。
A26: 常規物資 | B26: 水 | C26: 虛空泵機 | D26: 否 | E26: -
A27: 常規物資 | B27: 虛空 | C27: 虛空泵機 | D27: 否 | E27: -
A28: 常規物資 | B28: 槌子 | C28: 開局獲得 | D28: 否 | E28: - | G28: 可用於敲起植物進行移植 | H28: 拆除放置建物、管道等等
A29: 常規物資 | B29: 板手 | C29: 開局獲得 | D29: 否 | E29: - | H29: 改變物品管道內物品走向、機器輸入/出口設定
A30: 常規物資 | B30: 藍圖 | C30: 開局獲得 | D30: 否 | E30: -
A31: 常規物資 | B31: 橡皮擦 | C31: 創造模式開局獲得 | D31: 否 | E31: -
A32: 波莫拉 (Pomora) | B32: 草地 | C32: 地圖生成 | D32: 否 | E32: - | H32: 種植植物；不同草地效果皆相通
A33: 波莫拉 (Pomora) | B33: 鹽(礦石方塊) | C33: 採掘機直接開採 | D33: 否 | E33: -
A34: 波莫拉 (Pomora) | B34: 鹽 | C34: 採掘機 | D34: 否 | E34: -
A35: 波莫拉 (Pomora) | B35: 石頭 | C35: 地圖生成 | D35: 否 | E35: - | H35: 種植植物；不同石頭效果皆相通
A36: 波莫拉 (Pomora) | B36: 煤炭(礦石方塊) | C36: 地圖生成 | D36: 否 | E36: -
A37: 波莫拉 (Pomora) | B37: 鐵礦石 | C37: 採掘機 | D37: 否 | E37: -
A38: 波莫拉 (Pomora) | B38: 豆肉蔻(礦石方塊) | C38: 地圖生成 | D38: 否 | E38: -
A39: 波莫拉 (Pomora) | B39: 豆肉蔻 | C39: 採掘機 | D39: 否 | E39: -
A40: 波莫拉 (Pomora) | B40: 沙塊 | C40: 採掘機 | D40: 否 | E40: -
A41: 波莫拉 (Pomora) | B41: 日桂葉 | C41: 收割機 | D41: 否 | E41: -
A42: 波莫拉 (Pomora) | B42: 日桂葉植株 | C42: 地圖生成 | D42: 否 | E42: - | H42: 生長於石頭
A43: 波莫拉 (Pomora) | B43: 塔瑪茄 | C43: 收割機 | D43: 否 | E43: -
A44: 波莫拉 (Pomora) | B44: 塔瑪茄植株 | C44: 地圖生成 | D44: 否 | E44: - | H44: 生長於草地
A45: 波莫拉 (Pomora) | B45: 洋蔥蔥 | C45: 收割機 | D45: 否 | E45: -
A46: 波莫拉 (Pomora) | B46: 洋蔥蔥植株 | C46: 地圖生成 | D46: 否 | E46: - | H46: 生長於草地
...

Sheet 食譜
A1: 所屬島嶼/關卡 | B1: 食譜/料理名稱 | C1: 加工設備 | D1: 所需液體種類 | E1: 持續液體需求(fl/s) | F1: 固體原料1名稱 | G1: 固體原料1數量 | H1: 固體原料2名稱 | I1: 固體原料2數量 | J1: 固體原料3名稱 | K1: 固體原料3數量 | L1: 固體原料4名稱 | M1: 固體原料4數量 | N1: 製作時間(秒) | O1: 單次產出數量 | P1: 產出速率(個/秒) | Q1: 特殊製程注意事項
A2: 波莫拉 (Pomora) | B2: 鮮紅濃湯 | C2: 自動廚師機 | D2: 塔瑪茄醬 | E2: 1 | F2: 豆肉蔻 | G2: 1 | H2: 鹽 | I2: 1 | J2: 日桂葉 | K2: 1 | L2: 無 | M2: 0 | N2: 5 | O2: 1 | P2: =O2/N2 -> 0.2 | Q2: 需持續通入攪拌機產出之塔瑪茄醬(1 fl/s)；含有過敏原(豆肉蔻)。
A3: 波莫拉 (Pomora) | B3: 蜘蛛意式通心粉 | C3: 自動廚師機 | D3: 塔瑪茄醬 | E3: 1 | F3: 煮熟的通心粉 | G3: 1 | H3: 日桂葉 | I3: 1 | J3: 無 | K3: 0 | L3: 無 | M3: 0 | N3: 5 | O3: 1 | P3: =O3/N3 -> 0.2 | Q3: 需持續通入塔瑪茄醬(1 fl/s)；由蜘蛛蛋與骨粉製成通心粉。
A4: 波莫拉 (Pomora) | B4: 惡鬼千層面 | C4: 自動廚師機 | D4: 塔瑪茄醬 | E4: 1 | F4: 煮熟的千層麵皮 | G4: 1 | H4: 史萊姆肉餡 | I4: 1 | J4: 日桂葉 | K4: 1 | L4: 無 | M4: 0 | N4: 5 | O4: 1 | P4: =O4/N4 -> 0.2 | Q4: 需持續通入塔瑪茄醬(1 fl/s)；廚師機固體食材配比皆為 1:1。
A5: 波莫拉 (Pomora) | B5: 幽靈肉醬意麵 | C5: 自動廚師機 | D5: 塔瑪茄醬 | E5: 1 | F5: 煮熟的義大利麵 | G5: 1 | H5: 史萊姆肉餡 | I5: 1 | J5: 無 | K5: 0 | L5: 無 | M5: 0 | N5: 5 | O5: 1 | P5: =O5/N5 -> 0.2 | Q5: 需通入塔瑪茄醬(1 fl/s)；由熟義大利麵、史萊姆肉餡組裝而成。
A6: 波莫拉 (Pomora) | B6: 哀嚎肉丸 | C6: 自動廚師機 | D6: 塔瑪茄醬 | E6: 1 | F6: 炸史萊姆肉丸 | G6: 1 | H6: 日桂葉 | I6: 1 | J6: 無 | K6: 0 | L6: 無 | M6: 0 | N6: 5 | O6: 1 | P6: =O6/N6 -> 0.2 | Q6: 需持續通入塔瑪茄醬(1 fl/s)；由炸史萊姆肉丸與日桂葉組裝而成。
A7: 波莫拉 (Pomora) | B7: 塔瑪茄炒蛋 | C7: 自動廚師機 | D7: 無 | E7: 0 | F7: 炒蜘蛛蛋 | G7: 1 | H7: 塔瑪茄 | I7: 1 | J7: 豆肉蔻 | K7: 1 | L7: 無 | M7: 0 | N7: 5 | O7: 1 | P7: =O7/N7 -> 0.2 | Q7: 無需通入液體；由炒蜘蛛蛋、塔瑪茄與豆肉蔻組裝而成。
A8: 波莫拉 (Pomora) | B8: 瘟疫青醬麵 | C8: 自動廚師機 | D8: 青醬 | E8: 1 | F8: 煮熟的通心粉 | G8: 1 | H8: 鹽 | I8: 1 | J8: 無 | K8: 0 | L8: 無 | M8: 0 | N8: 5 | O8: 1 | P8: =O8/N8 -> 0.2 | Q8: 需持續通入青醬(1 fl/s)；由煮熟的通心粉與鹽組裝而成。
A9: 波莫拉 (Pomora) | B9: 煉獄魔蛋 | C9: 自動廚師機 | D9: 塔瑪茄醬 | E9: 1 | F9: 炸蜘蛛蛋 | G9: 1 | H9: 日桂葉 | I9: 1 | J9: 無 | K9: 0 | L9: 無 | M9: 0 | N9: 5 | O9: 1 | P9: =O9/N9 -> 0.2 | Q9: 需持續通入塔瑪茄醬(1 fl/s)；由炸蜘蛛蛋與日桂葉組裝而成。
A10: 波莫拉 (Pomora) | B10: 驚魂北非蛋 | C10: 自動廚師機 | D10: 塔瑪茄醬 | E10: 1 | F10: 炸蜘蛛蛋 | G10: 1 | H10: 塔瑪茄泥 | I10: 1 | J10: 豆肉蔻 | K10: 1 | L10: 無 | M10: 0 | N10: 5 | O10: 1 | P10: =O10/N10 -> 0.2 | Q10: 需持續通入塔瑪茄醬(1 fl/s)；由炸蜘蛛蛋、塔瑪茄泥與豆肉蔻組裝而成。
A11: 波莫拉 (Pomora) | B11: 撕裂脆片蘸醬 | C11: 自動廚師機 | D11: 塔瑪茄醬 | E11: 1 | F11: 多林多滋 | G11: 1 | H11: 鹽 | I11: 1 | J11: 無 | K11: 0 | L11: 無 | M11: 0 | N11: 5 | O11: 1 | P11: =O11/N11 -> 0.2 | Q11: 需持續通入塔瑪茄醬(1 fl/s)；由多林多滋與鹽組裝而成。
A12: 波莫拉 (Pomora) | B12: 惡臭農場蛋 | C12: 自動廚師機 | D12: 無 | E12: 0 | F12: 玉米餅 | G12: 1 | H12: 塔瑪茄泥 | I12: 1 | J12: 炸蜘蛛蛋 | K12: 1 | L12: ·椒 | M12: 1 | N12: 5 | O12: 1 | P12: =O12/N12 -> 0.2 | Q12: 無需通入液體；由玉米餅、塔瑪茄泥、炸蜘蛛蛋與·椒組裝而成。
A13: 波莫拉 (Pomora) | B13: 致命玉米片 | C13: 自動廚師機 | D13: 塔瑪茄醬 | E13: 1 | F13: 多林多滋 | G13: 1 | H13: 炒蜘蛛蛋 | I13: 1 | J13: 豆肉蔻 | K13: 1 | L13: ·椒 | M13: 1 | N13: 5 | O13: 1 | P13: =O13/N13 -> 0.2 | Q13: 需持續通入塔瑪茄醬(1 fl/s)；由多林多滋、炒蜘蛛蛋、豆肉蔻與·椒組裝而成。
... A23: 克洛文納 (Clovina) | B23: 怪物庫克先生 | C23: 自動廚師機 | D23: 白醬 | E23: 1 | F23: 麵包 | G23: 1 | H23: 中等熟成奶酪 | I23: 1 | J23: 無 | K23: 0 | L23: 無 | M23: 0 | N23: 5 | O23: 1 | P23: =O23/N23 -> 0.2 | Q23: 需持續通入白醬(1 fl/s)；由麵包與中等熟成奶酪組裝而成。
A24: 克洛文納 (Clovina) | B24: 墳墓土豆塊 | C24: 自動廚師機 | D24: 油 | E24: 1 | F24: 土豆 | G24: 1 | H24: 香豆蔻 | I24: 1 | J24: 小蒜 | K24: 1 | L24: 塔瑪茄 | M24: 1 | N24: 5 | O24: 1 | P24: 0.2 | Q24: 需持續通入油(1 fl/s)；由土豆、香豆蔻、小蒜與塔瑪茄組裝而成；含有氣味刺鼻原料。
A25: 克洛文納 (Clovina) | B25: 爆炸土豆塊 | C25: 自動廚師機 | D25: 肉汁 | E25: 1 | F25: 土豆 | G25: 1 | H25: 香豆蔻 | I25: 1 | J25: 小蒜 | K25: 1 | L25: 歐琴 | M25: 1 | N25: 5 | O25: 1 | P25: 0.2 | Q25: 需持續通入肉汁(1 fl/s)；由土豆、香豆蔻、小蒜與歐琴組裝而成；含有氣味刺鼻原料。
A26: 克洛文納 (Clovina) | B26: 奶酪飛濺盤 | C26: 自動廚師機 | D26: 無 | E26: 0 | F26: 軟質奶酪 | G26: 1 | H26: 中等熟成奶酪 | I26: 1 | J26: 藍紋奶酪 | K26: 1 | L26: 麵包 | M26: 1 | N26: 5 | O26: 1 | P26: 0.2 | Q26: 無需液體；由軟質奶酪、中等熟成奶酪、藍紋奶酪與麵包組裝而成；涉及 20s/30s/60s 三階時序熟成。
A27: 克洛文納 (Clovina) | B27: 恐慌帕尼爾 | C27: 自動廚師機 | D27: 肉汁 | E27: 1 | F27: 軟質奶酪 | G27: 1 | H27: 炸小蒜 | I27: 1 | J27: 蟑螂奶油 | K27: 1 | L27: 歐琴 | M27: 1 | N27: 5 | O27: 1 | P27: =O27/N27 -> 0.2 | Q27: 需持續通入肉汁(1 fl/s)；由軟質奶酪、炸小蒜、蟑螂奶油與歐琴組裝而成。
A28: 克洛文納 (Clovina) | B28: 殺戮芝士麵 | C28: 自動廚師機 | D28: 無 | E28: 0 | F28: 硬質奶酪 | G28: 1 | H28: 煮熟的通心粉 | I28: 1 | J28: 蟑螂黃油 | K28: 1 | L28: 歐琴 | M28: 1 | N28: 5 | O28: 1 | P28: 0.2 | Q28: 無需液體；由硬質奶酪、煮熟的通心粉、蟑螂黃油與歐琴組裝而成；涉及 20s+30s 奶酪時序熟成。
A29: 克洛文納 (Clovina) | B29: 恐懼炸芝士 | C29: 自動廚師機 | D29: 麵糊 | E29: 1 | F29: 中等熟成奶酪 | G29: 1 | H29: 麵包糠 | I29: 1 | J29: 無 | K29: 0 | L29: 無 | M29: 0 | N29: 5 | O29: 1 | P29: 0.2 | Q29: 需持續通入麵糊(1 fl/s)；由中等熟成奶酪與麵包糠組裝而成；涉及奶酪與麵團時序發酵。
A30: 克洛文納 (Clovina) | B30: 毒蘑菇·肉 | C30: 自動廚師機 | D30: 肉汁 | E30: 1 | F30: 綠色史萊姆 | G30: 1 | H30: 致命傘菇 | I30: 1 | J30: 酸奶油 | K30: 1 | L30: 香豆蔻 | M30: 1 | N30: 5 | O30: 1 | P30: 0.2 | Q30: 需持續通入肉汁(1 fl/s)；由綠色史萊姆、致命傘菇、酸奶油與香豆蔻組裝而成；具食物中毒屬性。
A31: 克洛文納 (Clovina) | B31: 罪人炒飯 | C31: 自動廚師機 | D31: 無 | E31: 0 | F31: 打工小妖炒飯 | G31: 1 | H31: 炸小蒜 | I31: 1 | J31: 香豆蔻 | K31: 1 | L31: 無 | M31: 0 | N31: 5 | O31: 1 | P31: =O31/N31 -> 0.2 | Q31: 無需通入液體；由打工小妖炒飯、炸小蒜與香豆蔻組裝而成。
A32: 克洛文納 (Clovina) | B32: 骨味炸米團 | C32: 自動廚師機 | D32: 麵糊 | E32: 1 | F32: 軟質奶酪 | G32: 1 | H32: 水稻 | I32: 1 | J32: 麵包糠 | K32: 1 | L32: 無 | M32: 0 | N32: 5 | O32: 1 | P32: =O32/N32 -> 0.2 | Q32: 需持續通入麵糊 (1 fl/s)；由軟質奶酪、水稻與麵包糠組裝而成。
A33: 克洛文納 (Clovina) | B33: 撒旦紅燴飯 | C33: 自動廚師機 | D33: 塔瑪茄醬 | E33: 1 | F33: 硬質奶酪 | G33: 1 | H33: 蟑螂黃油 | I33: 1 | J33: 水稻 | K33: 1 | L33: ·椒 | M33: 1 | N33: 5 | O33: 1 | P33: 0.2 | Q33: 需通入塔瑪茄醬(1 fl/s)；由硬質奶酪、蟑螂黃油、水稻與·椒組裝；涉及奶酪50秒二階時序熟成。
A34: 克洛文納 (Clovina) | B34: 幽靈肉汁奶酪薯條 | C34: 自動廚師機 | D34: 肉汁 | E34: 1 | F34: 薯條 | G34: 1 | H34: 芝士碎 | I34: 1 | J34: 無 | K34: 0 | L34: 無 | M34: 0 | N34: 5 | O34: 1 | P34: =O34/N34 -> 0.2 | Q34: 需持續通入肉汁(1 fl/s)；由薯條與芝士碎組裝而成；芝士碎由中等熟成奶酪(20s熟成)研磨；含有小蒜(氣味刺鼻)。
A35: 克洛文納 (Clovina) | B35: 痛擊漢堡 | C35: 自動廚師機 | D35: 無 | E35: 0 | F35: 史萊姆肉餡 | G35: 1 | H35: 麵包 | I35: 1 | J35: 芝士碎 | K35: 1 | L35: 薯條 | M35: 1 | N35: 5 | O35: 1 | P35: =O35/N35 -> 0.2 | Q35: 無需液體；由史萊姆肉餡、麵包、芝士碎與薯條組裝而成；涉及奶酪與麵團時序發酵。
A36: 克洛文納 (Clovina) | B36: 刺菠蘿披薩 | C36: 自動廚師機 | D36: 塔瑪茄醬 | E36: 1 | F36: 麵包 | G36: 1 | H36: 芝士碎 | I36: 1 | J36: 刺菠蘿 | K36: 1 | L36: 薯條 | M36: 1 | N36: 5 | O36: 1 | P36: =O36/N36 -> 0.2 | Q36: 需持續通入塔瑪茄醬(1 fl/s)；由麵包、芝士碎、刺菠蘿與薯條組裝而成；含有刺菠蘿(氣味刺鼻)。
A37: 克洛文納 (Clovina) | B37: 殺手薄餅 | C37: 自動廚師機 | D37: 塔瑪茄醬 | E37: 1 | F37: 玉米餅 | G37: 1 | H37: 史萊姆肉餡 | I37: 1 | J37: 芝士碎 | K37: 1 | L37: 酸奶油 | M37: 1 | N37: 5 | O37: 1 | P37: =O37/N37 -> 0.2 | Q37: 需持續通入塔瑪茄醬(1 fl/s)；由玉米餅、史萊姆肉餡、芝士碎與酸奶油組裝而成；涉及奶酪與奶油雙重時序熟成。
A38: 克洛文納 (Clovina) | B38: 混亂日式炒飯 | C38: 自動廚師機 | D38: 油 | E38: 1 | F38: 打工小妖炒飯 | G38: 1 | H38: 臭蛇蛋 | I38: 1 | J38: 香豆蔻 | K38: 1 | L38: 小蒜 | M38: 1 | N38: 5 | O38: 1 | P38: =O38/N38 -> 0.2 | Q38: 需持續通入油(1 fl/s)；由打工小妖炒飯、臭蛇蛋、香豆蔻與小蒜組裝而成；涉及蛇蛋30秒時序腐壞。
A39: 斯科瓦拉 | B39: 爆烈雞肉飯 | C39: 自動廚師機 | D39: 炙烈紅油 | E39: 1 | F39: 打工小妖炒飯 | G39: 1 | H39: 生鷹身女妖肉 | I39: 1 | J39: 菠菜 | K39: 1 | L39: 辛辣沙沙醬 | M39: 1 | N39: 5 | O39: 1 | P39: =O39/N39 -> 0.2 | Q39: 需持續通入炙烈紅油(1 fl/s)；由打工小妖炒飯、生鷹身女妖肉、菠菜與辛辣沙沙醬組裝而成；生鷹身女妖肉具食物中毒屬性。
A40: 斯科瓦拉 | B40: 驚嚇醃薑 | C40: 自動廚師機 | D40: 無 | E40: 0 | F40: 醋 | G40: 1 | H40: 姜姜 | I40: 1 | J40: E127 | K40: 1 | L40: 無 | M40: 0 | N40: 5 | O40: 1 | P40: 0.2 | Q40: 由醋、姜姜與E127組裝而成；E127具氣味刺鼻屬性。

Sheet 圖片對照表
A1: 類別 | B1: 名稱 | C1: 遊戲圖示 (貼圖處) | D1: 功能說明 / 特性備註
A2: 必備機器 | B2: 熔爐
A3: 必備機器 | B3: 分撿機
A4: 必備機器 | B4: 裝配機
A5: 必備機器 | B5: 送餐大炮
A6: 必備機器 | B6: 儲物箱
A7: 必備機器 | B7: 分流器
A8: 收割機器 | B8: 採掘機
A9: 收割機器 | B9: 虛空泵機
A10: 收割機器 | B10: 收割機
A11: 轉化機器 | B11: 發酵罐
A12: 轉化機器 | B12: 油炸鍋
A13: 轉化機器 | B13: 注入機
... A118: 克洛文納 (Clovina) | B118: 白醬
A119: 常規物資 | B119: 骨粉 | D119: 巫妖骸骨研磨產物，用於合成義大利麵團。
A120: 波莫拉 (Pomora) | B120: 史萊姆肉餡 | D120: 綠色史萊姆研磨產出，用於製作千層面。
A121: 波莫拉 (Pomora) | B121: 幽靈肉醬意麵 | D121: 波莫拉終端料理：幽靈肉醬意麵
A122: 波莫拉 (Pomora) | B122: 生史萊姆肉丸 | D122: 混合機產物（生肉丸）
A123: 波莫拉 (Pomora) | B123: 炸史萊姆肉丸 | D123: 油炸鍋產物（熟肉丸）
A124: 波莫拉 (Pomora) | B124: 炒蜘蛛蛋 | D124: 混合機產物（炒蛋）
A125: 波莫拉 (Pomora) | B125: 炸蜘蛛蛋 | D125: 油炸鍋產物（炸蛋）
A126: 波莫拉 (Pomora) | B126: 煉獄魔蛋 | D126: 波莫拉終端料理
A127: 波莫拉 (Pomora) | B127: 塔瑪茄泥 | D127: 混合機產物（紅泥）
A128: 波莫拉 (Pomora) | B128: 驚魂北非蛋 | D128: 波莫拉終端料理
A129: 波莫拉 (Pomora) | B129: 生玉米餅 | D129: 混合機產物（生麵團）
A130: 克洛文納 (Clovina) | B130: 麵包糠 | D130: 由麵包經研磨機磨成，用於恐懼炸芝士裹粉
... A135: 克洛文納 (Clovina) | B135: 芝士碎 | D135: 中等熟成奶酪經研磨機磨成，每次2個
A136: 斯科瓦拉 | B136: 乾燥草地
A137: 斯科瓦拉 | B137: 砂岩
A138: 斯科瓦拉 | B138: 冰塊
A139: 斯科瓦拉 | B139: 菠菜
A140: 斯科瓦拉 | B140: 菠菜植株
A141: 斯科瓦拉 | B141: 油荳蔻
A142: 斯科瓦拉 | B142: 油荳蔻植株
A143: 斯科瓦拉 | B143: 松子
A144: 斯科瓦拉 | B144: 松樹
A145: 斯科瓦拉 | B145: 姜姜
A146: 斯科瓦拉 | B146: 姜姜塊莖
A147: 斯科瓦拉 | B147: 辣椒
... A150: 斯科瓦拉 | B150: 哈瓦那魔椒
...

Sheet 計算機參數庫
A1: 料理名稱 | B1: 工序名稱 | C1: 使用設備 | D1: 單台基準速率 | E1: 單台電力 | F1: 單台小妖精 | G1: 排序 | I1: 料理名稱 | J1: 食材名稱 | K1: 單份消耗量 | L1: 類型 | N1: 料理選單清單
A2: 鮮紅濃湯 | B2: 終端組裝 | C2: 自動廚師機 | D2: 0.2 | E2: 1 | F2: 3 | G2: 1 | I2: 鮮紅濃湯 | J2: 塔瑪茄 | K2: 1 | L2: 固體 | N2: (無)
A3: 鮮紅濃湯 | B3: 塔瑪茄醬 | C3: 攪拌機 | D3: 0.2 | E3: 1 | F3: 2 | G3: 2 | I3: 鮮紅濃湯 | J3: 日桂葉 | K3: 2 | L3: 固體 | N3: =IFERROR(__xludf.DUMMYFUNCTION("FILTER('食譜'!$B$2:$B1001, '食譜'!$B$2:$B1001<>"""")"),"鮮紅濃湯") -> 鮮紅濃湯
A4: 鮮紅濃湯 | B4: 採收塔瑪茄 | C4: 收割機 | D4: 0.2 | E4: 1 | F4: 1 | G4: 3 | I4: 鮮紅濃湯 | J4: 豆肉蔻 | K4: 1 | L4: 固體 | N4: =IFERROR(__xludf.DUMMYFUNCTION("""COMPUTED_VALUE"""),"蜘蛛意式通心粉") -> 蜘蛛意式通心粉
A5: 鮮紅濃湯 | B5: 採收日桂葉 | C5: 收割機 | D5: 0.1 | E5: 1 | F5: 1 | G5: 4 | I5: 鮮紅濃湯 | J5: 鹽 | K5: 1 | L5: 固體 | N5: =IFERROR(__xludf.DUMMYFUNCTION("""COMPUTED_VALUE"""),"惡鬼千層面") -> 惡鬼千層面
A6: 鮮紅濃湯 | B6: 開採豆肉蔻 | C6: 採掘機 | D6: 0.2 | E6: 1 | F6: 1 | G6: 5 | I6: 蜘蛛意式通心粉 | J6: 塔瑪茄 | K6: 1 | L6: 固體 | N6: =IFERROR(__xludf.DUMMYFUNCTION("""COMPUTED_VALUE"""),"幽靈肉醬意麵") -> 幽靈肉醬意麵
A7: 鮮紅濃湯 | B7: 開採鹽 | C7: 採掘機 | D7: 0.2 | E7: 1 | F7: 1 | G7: 6 | I7: 蜘蛛意式通心粉 | J7: 日桂葉 | K7: 2 | L7: 固體 | N7: =IFERROR(__xludf.DUMMYFUNCTION("""COMPUTED_VALUE"""),"哀嚎肉丸") -> 哀嚎肉丸
A8: 蜘蛛意式通心粉 | B8: 終端組裝 | C8: 自動廚師機 | D8: 0.2 | E8: 1 | F8: 3 | G8: 1 | I8: 蜘蛛意式通心粉 | J8: 巫妖骸骨 | K8: 0.5 | L8: 固體 | N8: =IFERROR(__xludf.DUMMYFUNCTION("""COMPUTED_VALUE"""),"塔瑪茄炒蛋") -> 塔瑪茄炒蛋
A9: 蜘蛛意式通心粉 | B9: 塔瑪茄醬 | C9: 攪拌機 | D9: 0.2 | E9: 1 | F9: 2 | G9: 2 | I9: 蜘蛛意式通心粉 | J9: 蜘蛛蛋 | K9: 1 | L9: 固體 | N9: =IFERROR(__xludf.DUMMYFUNCTION("""COMPUTED_VALUE"""),"瘟疫青醬麵") -> 瘟疫青醬麵
A10: 蜘蛛意式通心粉 | B10: 水煮通心粉 | C10: 煮鍋 | D10: 0.2 | E10: 1 | F10: 2 | G10: 3 | I10: 蜘蛛意式通心粉 | J10: 水 | K10: 1 | L10: 液體 | N10: =IFERROR(__xludf.DUMMYFUNCTION("""COMPUTED_VALUE"""),"煉獄魔蛋") -> 煉獄魔蛋
A11: 蜘蛛意式通心粉 | B11: 擠出通心粉 | C11: 擠出機 | D11: 0.25 | E11: 1 | F11: 2 | G11: 4 | I11: 惡鬼千層面 | J11: 巫妖骸骨 | K11: 0.5 | L11: 固體 | N11: =IFERROR(__xludf.DUMMYFUNCTION("""COMPUTED_VALUE"""),"驚魂北非蛋") -> 驚魂北非蛋
A12: 蜘蛛意式通心粉 | B12: 混和麵團 | C12: 混合機 | D12: 0.25 | E12: 1 | F12: 2 | G12: 5 | I12: 惡鬼千層面 | J12: 綠色史萊姆 | K12: 0.5 | L12: 固體 | N12: =IFERROR(__xludf.DUMMYFUNCTION("""COMPUTED_VALUE"""),"撕裂脆片蘸醬") -> 撕裂脆片蘸醬
A13: 蜘蛛意式通心粉 | B13: 研磨骨粉 | C13: 研磨機 | D13: 1 | E13: 1 | F13: 2 | G13: 6 | I13: 幽靈肉醬意麵 | J13: 塔瑪茄 | K13: 1 | L13: 固體 | N13: =IFERROR(__xludf.DUMMYFUNCTION("""COMPUTED_VALUE"""),"惡臭農場蛋") -> 惡臭農場蛋
A14: 蜘蛛意式通心粉 | B14: 重構巫妖骸骨 | C14: 物質操縱機 | D14: 0.4 | E14: 1 | F14: 1 | G14: 7 | I14: 幽靈肉醬意麵 | J14: 日桂葉 | K14: 1 | L14: 固體 | N14: =IFERROR(__xludf.DUMMYFUNCTION("""COMPUTED_VALUE"""),"致命玉米片") -> 致命玉米片
A15: 蜘蛛意式通心粉 | B15: 重構蜘蛛蛋 | C15: 物質操縱機 | D15: 0.2 | E15: 1 | F15: 1 | G15: 8 | I15: 幽靈肉醬意麵 | J15: 巫妖骸骨 | K15: 0.5 | L15: 固體 | N15: =IFERROR(__xludf.DUMMYFUNCTION("""COMPUTED_VALUE"""),"食屍鬼鮮莎莎") -> 食屍鬼鮮莎莎
A16: 蜘蛛意式通心粉 | B16: 採收塔瑪茄 | C16: 收割機 | D16: 0.2 | E16: 1 | F16: 1 | G16: 9 | I16: 幽靈肉醬意麵 | J16: 蜘蛛蛋 | K16: 1 | L16: 固體 | N16: =IFERROR(__xludf.DUMMYFUNCTION("""COMPUTED_VALUE"""),"幽靈洋蔥湯") -> 幽靈洋蔥湯
A17: 蜘蛛意式通心粉 | B17: 採收日桂葉 | C17: 收割機 | D17: 0.1 | E17: 1 | F17: 1 | G17: 10 | I17: 幽靈肉醬意麵 | J17: 綠色史萊姆 | K17: 0.5 | L17: 固體 | N17: =IFERROR(__xludf.DUMMYFUNCTION("""COMPUTED_VALUE"""),"驚嚇炸洋蔥") -> 驚嚇炸洋蔥
A18: 惡鬼千層面 | B18: 終端組裝 | C18: 自動廚師機 | D18: 0.2 | E18: 1 | F18: 3 | G18: 1 | I18: 幽靈肉醬意麵 | J18: 水 | K18: 1 | L18: 液體 | N18: =IFERROR(__xludf.DUMMYFUNCTION("""COMPUTED_VALUE"""),"暗淡洋蔥花") -> 暗淡洋蔥花
A19: 惡鬼千層面 | B19: 塔瑪茄醬 | C19: 攪拌機 | D19: 0.2 | E19: 1 | F19: 2 | G19: 2 | I19: 哀嚎肉丸 | J19: 塔瑪茄 | K19: 1 | L19: 固體 | N19: =IFERROR(__xludf.DUMMYFUNCTION("""COMPUTED_VALUE"""),"末日麵團") -> 末日麵團
A20: 惡鬼千層面 | B20: 水煮千層麵皮 | C20: 煮鍋 | D20: 0.2 | E20: 1 | F20: 2 | G20: 3 | I20: 哀嚎肉丸 | J20: 日桂葉 | K20: 2 | L20: 固體 | N20: =IFERROR(__xludf.DUMMYFUNCTION("""COMPUTED_VALUE"""),"咒語餃子") -> 咒語餃子
A21: 惡鬼千層面 | B21: 擠出千層麵皮 | C21: 擠出機 | D21: 0.25 | E21: 1 | F21: 2 | G21: 4 | I21: 哀嚎肉丸 | J21: 豆肉蔻 | K21: 1 | L21: 固體 | N21: =IFERROR(__xludf.DUMMYFUNCTION("""COMPUTED_VALUE"""),"墳墓茄包") -> 墳墓茄包
A22: 惡鬼千層面 | B22: 混和麵團 | C22: 混合機 | D22: 0.25 | E22: 1 | F22: 2 | G22: 5 | I22: 哀嚎肉丸 | J22: 綠色史萊姆 | K22: 1 | L22: 固體 | N22: =IFERROR(__xludf.DUMMYFUNCTION("""COMPUTED_VALUE"""),"暴徒烤麵包") -> 暴徒烤麵包
A23: 惡鬼千層面 | B23: 研磨骨粉 | C23: 研磨機 | D23: 1 | E23: 1 | F23: 2 | G23: 6 | I23: 哀嚎肉丸 | J23: 油 | K23: 1 | L23: 液體 | N23: =IFERROR(__xludf.DUMMYFUNCTION("""COMPUTED_VALUE"""),"爛蛋約翰") -> 爛蛋約翰
A24: 惡鬼千層面 | B24: 絞碎史萊姆 | C24: 研磨機 | D24: 1 | E24: 1 | F24: 2 | G24: 7 | I24: 哀嚎肉丸 | J24: 虛空 | K24: 1 | L24: 液體 | N24: =IFERROR(__xludf.DUMMYFUNCTION("""COMPUTED_VALUE"""),"怪物庫克先生") -> 怪物庫克先生
A25: 惡鬼千層面 | B25: 重構巫妖骸骨 | C25: 物質操縱機 | D25: 0.4 | E25: 1 | F25: 1 | G25: 8 | I25: 塔瑪茄炒蛋 | J25: 塔瑪茄 | K25: 1 | L25: 固體 | N25: =IFERROR(__xludf.DUMMYFUNCTION("""COMPUTED_VALUE"""),"墳墓土豆塊") -> 墳墓土豆塊
A26: 惡鬼千層面 | B26: 重構蜘蛛蛋 | C26: 物質操縱機 | D26: 0.2 | E26: 1 | F26: 1 | G26: 9 | I26: 塔瑪茄炒蛋 | J26: 豆肉蔻 | K26: 1 | L26: 固體 | N26: =IFERROR(__xludf.DUMMYFUNCTION("""COMPUTED_VALUE"""),"爆炸土豆塊") -> 爆炸土豆塊
A27: 惡鬼千層面 | B27: 重構綠色史萊姆 | C27: 物質操縱機 | D27: 0.4 | E27: 1 | F27: 1 | G27: 10 | I27: 塔瑪茄炒蛋 | J27: 鹽 | K27: 1 | L27: 固體 | N27: =IFERROR(__xludf.DUMMYFUNCTION("""COMPUTED_VALUE"""),"奶酪飛濺盤") -> 奶酪飛濺盤
A28: 惡鬼千層面 | B28: 採收塔瑪茄 | C28: 收割機 | D28: 0.2 | E28: 1 | F28: 1 | G28: 11 | I28: 塔瑪茄炒蛋 | J28: 蜘蛛蛋 | K28: 1 | L28: 固體 | N28: =IFERROR(__xludf.DUMMYFUNCTION("""COMPUTED_VALUE"""),"恐慌帕尼爾") -> 恐慌帕尼爾
A29: 惡鬼千層面 | B29: 採收日桂葉 | C29: 收割機 | D29: 0.1 | E29: 1 | F29: 1 | G29: 12 | I29: 塔瑪茄炒蛋 | J29: 虛空 | K29: 1 | L29: 液體 | N29: =IFERROR(__xludf.DUMMYFUNCTION("""COMPUTED_VALUE"""),"殺戮芝士麵") -> 殺戮芝士麵
A30: 幽靈肉醬意麵 | B30: 終端組裝 | C30: 自動廚師機 | D30: 0.2 | E30: 1 | F30: 3 | G30: 1 | I30: 瘟疫青醬麵 | J30: 巫妖骸骨 | K30: 0.5 | L30: 固體 | N30: =IFERROR(__xludf.DUMMYFUNCTION("""COMPUTED_VALUE"""),"恐懼炸芝士") -> 恐懼炸芝士
A31: 幽靈肉醬意麵 | B31: 塔瑪茄醬 | C31: 攪拌機 | D31: 0.2 | E31: 1 | F31: 2 | G31: 2 | I31: 瘟疫青醬麵 | J31: 蜘蛛蛋 | K31: 1 | L31: 固體 | N31: =IFERROR(__xludf.DUMMYFUNCTION("""COMPUTED_VALUE"""),"毒蘑菇·肉") -> 毒蘑菇·肉
A32: 幽靈肉醬意麵 | B32: 水煮義大利麵 | C32: 煮鍋 | D32: 0.2 | E32: 1 | F32: 2 | G32: 3 | I32: 瘟疫青醬麵 | J32: 日桂葉 | K32: 1 | L32: 固體 | N32: =IFERROR(__xludf.DUMMYFUNCTION("""COMPUTED_VALUE"""),"罪人炒飯") -> 罪人炒飯
A33: 幽靈肉醬意麵 | B33: 擠出義大利麵 | C33: 擠出機 | D33: 0.25 | E33: 1 | F33: 2 | G33: 4 | I33: 瘟疫青醬麵 | J33: 豆肉蔻 | K33: 1 | L33: 固體 | N33: =IFERROR(__xludf.DUMMYFUNCTION("""COMPUTED_VALUE"""),"骨味炸米團") -> 骨味炸米團
A34: 幽靈肉醬意麵 | B34: 混和麵團 | C34: 混合機 | D34: 0.25 | E34: 1 | F34: 2 | G34: 5 | I34: 瘟疫青醬麵 | J34: 鹽 | K34: 1 | L34: 固體 | N34: =IFERROR(__xludf.DUMMYFUNCTION("""COMPUTED_VALUE"""),"撒旦紅燴飯") -> 撒旦紅燴飯
A35: 幽靈肉醬意麵 | B35: 研磨骨粉 | C35: 研磨機 | D35: 1 | E35: 1 | F35: 2 | G35: 6 | I35: 瘟疫青醬麵 | J35: 水 | K35: 1 | L35: 液體 | N35: =IFERROR(__xludf.DUMMYFUNCTION("""COMPUTED_VALUE"""),"幽靈肉汁奶酪薯條") -> 幽靈肉汁奶酪薯條
A36: 幽靈肉醬意麵 | B36: 絞碎史萊姆 | C36: 研磨機 | D36: 1 | E36: 1 | F36: 2 | G36: 7 | I36: 瘟疫青醬麵 | J36: 虛空 | K36: 2 | L36: 液體 | N36: =IFERROR(__xludf.DUMMYFUNCTION("""COMPUTED_VALUE"""),"痛擊漢堡") -> 痛擊漢堡
A37: 幽靈肉醬意麵 | B37: 重構巫妖骸骨 | C37: 物質操縱機 | D37: 0.4 | E37: 1 | F37: 1 | G37: 8 | I37: 煉獄魔蛋 | J37: 塔瑪茄 | K37: 1 | L37: 固體 | N37: =IFERROR(__xludf.DUMMYFUNCTION("""COMPUTED_VALUE"""),"刺菠蘿披薩") -> 刺菠蘿披薩
A38: 幽靈肉醬意麵 | B38: 重構蜘蛛蛋 | C38: 物質操縱機 | D38: 0.2 | E38: 1 | F38: 1 | G38: 9 | I38: 煉獄魔蛋 | J38: 日桂葉 | K38: 2 | L38: 固體 | N38: =IFERROR(__xludf.DUMMYFUNCTION("""COMPUTED_VALUE"""),"殺手薄餅") -> 殺手薄餅
A39: 幽靈肉醬意麵 | B39: 重構綠色史萊姆 | C39: 物質操縱機 | D39: 0.4 | E39: 1 | F39: 1 | G39: 10 | I39: 煉獄魔蛋 | J39: 蜘蛛蛋 | K39: 1 | L39: 固體 | N39: =IFERROR(__xludf.DUMMYFUNCTION("""COMPUTED_VALUE"""),"混亂日式炒飯") -> 混亂日式炒飯
A40: 幽靈肉醬意麵 | B40: 採收塔瑪茄 | C40: 收割機 | D40: 0.2 | E40: 1 | F40: 1 | G40: 11 | I40: 煉獄魔蛋 | J40: 油 | K40: 1 | L40: 液體 | N40: =IFERROR(__xludf.DUMMYFUNCTION("""COMPUTED_VALUE"""),"爆烈雞肉飯") -> 爆烈雞肉飯
...

Sheet 產線計算機
A1: 控制面板
A2: 目標料理名稱 | B2: 驚嚇醃薑 | C2: 發電運轉模式 | D2: 二級超頻 (16 FV/s)
A3: 目標產出速率 (個/秒) | B3: 0.2
A4: 每分鐘目標產量 | B4: =B3*60 -> 12
A7: 【全廠綜合總結算】 | E7: 【廠內調配醬汁清單】 | H7: 【轉化流體泵機與超頻階梯配置】 | M7: 【外採泵機流體與超頻階梯配置】
A8: 全廠實需設備台數 | B8: =SUM(D17:D100) -> 7 | C8: 獨立產線 (無節省) | D8: - | E8: 醬汁名稱 | F8: 來源設備 | G8: 需量(fl/s) | H8: 轉化流體 | I8: 總需量(fl/s) | J8: 二級超頻(8fl/s) | K8: 一級常規(2fl/s) | L8: 供汙泥操機 | M8: 外採流體 | N8: 總需量(fl/s) | O8: 二級超頻(8fl/s) | P8: 一級常規(2fl/s) | Q8: 供汙泥操機
A9: 主設備電力 (純料理) | B9: =SUM(H17:H100) -> 7 | C9: 重構底料收割機台數 | D9: =SUMIF(B17:B100, "物質操縱*", D17:D100) -> 1 | E9: =IFERROR(__xludf.DUMMYFUNCTION("IFERROR(UNIQUE(FILTER('計算機參數庫'!$B$2:$B$1002, ('計算機參數庫'!$A$2:$A$1002=$B$2) * ('計算機參數庫'!$C$2:$C$1002=""攪拌機""))), ""無"")"),"無") -> 無 | F9: =IF(E9="無", "-", IF(E9="", "", "攪拌機專線 (1:1)")) -> - | G9: =IF(E9="無", 0, IF(E9="", "", SUMIF($A$17:$A$100, E9, $D$17:$D$100)*1)) -> 0 | H9: =IFERROR(__xludf.DUMMYFUNCTION("IFERROR(UNIQUE(FILTER('計算機參數庫'!$B$2:$B$1002, ('計算機參數庫'!$A$2:$A$1002=$B$2) * ('計算機參數庫'!$C$2:$C$1002=""注入機""))), ""無"")"),"注入醋") -> 注入醋 | I9: =IF(OR(H9="無", H9=""), "", IF(H9="炙烈紅油", SUMIF($A$17:$A$100, "*組裝*", $D$17:$D$100)*1 + SUMIFS($D$17:$D$100, $B$17:$B$100, "混合機")*0.5, 1)) -> 1 | J9: =IF(OR(H9="無", H9="", I9=""), "", INT(I9/8) + IF(MOD(I9, 8) > IF(N11>0, 2, 6), 1, 0)) -> 0 | K9: =IF(OR(H9="無", H9="", I9=""), "", _xlfn.CEILING.MATH(IF(MOD(I9, 8) > IF(N11>0, 2, 6), 0, MOD(I9, 8)) / 2)) -> 1 | L9: =IF(J9="", "", J9) -> 0 | M9: 水 | N9: =MAX(IFERROR(SUMIFS('計算機參數庫'!$K$2:$K$1001, '計算機參數庫'!$I$2:$I$1001, $B$2, '計算機參數庫'!$J$2:$J$1001, "水") * ($B$3 / 0.2), 0), SUMIF(B17:B100, "煮鍋", D17:D100) + _xlfn.CEILING.MATH((SUMIFS(D17:D100, B17:B100, "混合機", A17:A100, "*麵包*") + SUMIFS(D17:D100, B17:B100, "混合機", A17:A100, "*黃油*")) / 2, 1)) -> 1 | O9: =IF(N9=0, 0, INT(N9/8) + IF(MOD(N9, 8) > IF(N11>0, 2, 6), 1, 0)) -> 0 | P9: =IF(N9=0, 0, _xlfn.CEILING.MATH(IF(MOD(N9, 8) > IF(N11>0, 2, 6), 0, MOD(N9, 8)) / 2)) -> 1 | Q9: =O9 -> 0
A10: 泵機與操機電力 | B10: =Q13 -> 4 | C10: =IF(D2="一級常規 (4 FV/s)", "所需虛空熔爐 [常規 4FV/s]", "所需虛空熔爐 [超頻 16FV/s]") -> 所需虛空熔爐 [超頻 16FV/s] | D10: =ROUNDUP((B9 + B10 + B11) / IF(D2="一級常規 (4 FV/s)", 3.5, 14), 0) -> 1 | F10: =IF(OR(E10="", E10="無"), "", "攪拌機專線 (1:1)") | G10: =IF(OR(E10="", E10="無"), "", SUMIF($A$17:$A$100, E10, $D$17:$D$100)*1) | J10: =IF(OR(H10="", H10="無", I10=""), "", INT(I10/8) + IF(MOD(I10, 8) > IF(N11>0, 2, 6), 1, 0)) | K10: =IF(OR(H10="", H10="無", I10=""), "", _xlfn.CEILING.MATH(IF(MOD(I10, 8) > IF(N11>0, 2, 6), 0, MOD(I10, 8)) / 2)) | L10: =IF(J10="", "", J10) | M10: 油 | N10: =MAX(IFERROR(SUMIFS('計算機參數庫'!$K$2:$K$1001, '計算機參數庫'!$I$2:$I$1001, $B$2, '計算機參數庫'!$J$2:$J$1001, "油") * ($B$3 / 0.2), 0), SUMIF(B17:B100, "油炸鍋", D17:D100) + _xlfn.CEILING.MATH(SUMIFS(D17:D100, B17:B100, "混合機", A17:A100, "*玉米餅*") / 2, 1)) -> 0 | O10: =IF(N10=0, 0, INT(N10/8) + IF(MOD(N10, 8) > IF(N11>0, 2, 6), 1, 0)) -> 0 | P10: =IF(N10=0, 0, _xlfn.CEILING.MATH(IF(MOD(N10, 8) > IF(N11>0, 2, 6), 0, MOD(N10, 8)) / 2)) -> 0 | Q10: =O10 -> 0
A11: 底料機耗電 | B11: =D9*1 -> 1 | C11: 總煤炭消耗 | D11: =D10*0.1 -> 0.1 | M11: 虛空 | N11: =SUMIF(B17:B100, "物質操縱*", D17:D100)*1 + Q9 + Q10 + SUM(L9:L13) + IF(D2="一級常規 (4 FV/s)", 0, ROUNDUP(D10/2, 0)*1) -> 2 | O11: =IF(N11=0, 0, INT(N11/7) + IF(MOD(N11,7)>2, 1, 0)) -> 0 | P11: =IF(N11=0, 0, IF(AND(MOD(N11,7)>0, MOD(N11,7)<=2), 1, 0)) -> 1 | Q11: =O11 -> 0
A12: 採煤機耗電 | B12: =D12*1 -> 1 | C12: 所需採煤機 | D12: =ROUNDUP(D10/2, 0) -> 1 | M12: 全廠泵機與操機台數 | N12: (含轉化與發電) | O12: =SUM(O9:O11) + SUM(J9:J13) -> 0 | P12: =SUM(P9:P11) + SUM(K9:K13) -> 3 | Q12: =SUM(Q9:Q11) + SUM(L9:L13) + IF(D2="一級常規 (4 FV/s)", 0, ROUNDUP(D10/2, 0)) -> 1
A13: ⚡ 全廠總電力負載 | B13: =SUM(B9:B12) -> 13 | C13: 👥 全廠總小妖精 | D13: =SUM(F17:F100) + D9 + D10 + D12 + B10 -> 19 | M13: 全廠泵機與操機電力 | N13: 總能耗(FV/s) | O13: - | P13: - | Q13: =(O12 + P12 + Q12)*1 -> 4
A15: 【產線工序設備清單 (動態展開)】
A16: 工序名稱 | B16: 使用設備 | C16: 單台基準速率 (份/秒) | D16: 所需設備台數 (台) | E16: 單台小妖精 (個) | F16: 小妖精需求小計 (個) | G16: 單台電力(FV/s) | H16: 電力負載小計(FV/s) | I16: 最簡整數比 | J16: 分流拓撲建議
A17: =IFERROR(__xludf.DUMMYFUNCTION("IFERROR(FILTER('計算機參數庫'!B2:D1001, '計算機參數庫'!A2:A1001 = $B$2), """")"),"終端組裝") -> 終端組裝 | B17: =IFERROR(__xludf.DUMMYFUNCTION("""COMPUTED_VALUE"""),"自動廚師機") -> 自動廚師機 | C17: =IFERROR(__xludf.DUMMYFUNCTION("""COMPUTED_VALUE"""),0.2) -> 0.2 | D17: =IF(A17="", "", ROUNDUP($B$3 / C17, 0)) -> 1 | E17: =IF(A17="", "", VLOOKUP(B17, '機器設備'!$B$2:$C$100, 2, FALSE)) -> 3 | F17: =IF(A17="", "", D17*E17) -> 3 | G17: =IF(A17="", "", VLOOKUP(B17, '機器設備'!$B$2:$D$100, 3, FALSE)) -> 1 | H17: =IF(A17="", "", D17*G17) -> 1 | I17: =IF(A17="", "", D17 / IFERROR(GCD($D$17:$D$100), 1)) -> 1 | J17: =IF(A17="", "", IF(B17="自動廚師機", "終端出餐 (大炮發射)", IF(B17="攪拌機", IF(I17=1, "1:1 專線通液 (1 fl/s)", IF(I17=2, "雙路專線通液 (各 1 fl/s)", "多路專線通液")), IF(I17=1, "1:1 對等直連", IF(I17=2, "1分2均等分流(自帶雙口)", "專用分流器拓撲"))))) -> 終端出餐 (大炮發射)
A18: =IFERROR(__xludf.DUMMYFUNCTION("""COMPUTED_VALUE"""),"注入醋") -> 注入醋 | B18: =IFERROR(__xludf.DUMMYFUNCTION("""COMPUTED_VALUE"""),"注入機") -> 注入機 | C18: =IFERROR(__xludf.DUMMYFUNCTION("""COMPUTED_VALUE"""),0.2) -> 0.2 | D18: =IF(A18="", "", ROUNDUP($B$3 / C18, 0)) -> 1 | E18: =IF(A18="", "", VLOOKUP(B18, '機器設備'!$B$2:$C$100, 2, FALSE)) -> 2 | F18: =IF(A18="", "", D18*E18) -> 2 | G18: =IF(A18="", "", VLOOKUP(B18, '機器設備'!$B$2:$D$100, 3, FALSE)) -> 1 | H18: =IF(A18="", "", D18*G18) -> 1 | I18: =IF(A18="", "", D18 / IFERROR(GCD($D$17:$D$100), 1)) -> 1 | J18: =IF(A18="", "", IF(B18="自動廚師機", "終端出餐 (大炮發射)", IF(B18="攪拌機", IF(I18=1, "1:1 專線通液 (1 fl/s)", IF(I18=2, "雙路專線通液 (各 1 fl/s)", "多路專線通液")), IF(I18=1, "1:1 對等直連", IF(I18=2, "1分2均等分流(自帶雙口)", "專用分流器拓撲"))))) -> 1:1 對等直連
A19: =IFERROR(__xludf.DUMMYFUNCTION("""COMPUTED_VALUE"""),"發酵甘酒") -> 發酵甘酒 | B19: =IFERROR(__xludf.DUMMYFUNCTION("""COMPUTED_VALUE"""),"發酵罐") -> 發酵罐 | C19: =IFERROR(__xludf.DUMMYFUNCTION("""COMPUTED_VALUE"""),0.5) -> 0.5 | D19: =IF(A19="", "", ROUNDUP($B$3 / C19, 0)) -> 1 | E19: =IF(A19="", "", VLOOKUP(B19, '機器設備'!$B$2:$C$100, 2, FALSE)) -> 2 | F19: =IF(A19="", "", D19*E19) -> 2 | G19: =IF(A19="", "", VLOOKUP(B19, '機器設備'!$B$2:$D$100, 3, FALSE)) -> 1 | H19: =IF(A19="", "", D19*G19) -> 1 | I19: =IF(A19="", "", D19 / IFERROR(GCD($D$17:$D$100), 1)) -> 1 | J19: =IF(A19="", "", IF(B19="自動廚師機", "終端出餐 (大炮發射)", IF(B19="攪拌機", IF(I19=1, "1:1 專線通液 (1 fl/s)", IF(I19=2, "雙路專線通液 (各 1 fl/s)", "多路專線通液")), IF(I19=1, "1:1 對等直連", IF(I19=2, "1分2均等分流(自帶雙口)", "專用分流器拓撲"))))) -> 1:1 對等直連
A20: =IFERROR(__xludf.DUMMYFUNCTION("""COMPUTED_VALUE"""),"採收水稻") -> 採收水稻 | B20: =IFERROR(__xludf.DUMMYFUNCTION("""COMPUTED_VALUE"""),"收割機") -> 收割機 | C20: =IFERROR(__xludf.DUMMYFUNCTION("""COMPUTED_VALUE"""),0.2) -> 0.2 | D20: =IF(A20="", "", ROUNDUP($B$3 / C20, 0)) -> 1 | E20: =IF(A20="", "", VLOOKUP(B20, '機器設備'!$B$2:$C$100, 2, FALSE)) -> 1 | F20: =IF(A20="", "", D20*E20) -> 1 | G20: =IF(A20="", "", VLOOKUP(B20, '機器設備'!$B$2:$D$100, 3, FALSE)) -> 1 | H20: =IF(A20="", "", D20*G20) -> 1 | I20: =IF(A20="", "", D20 / IFERROR(GCD($D$17:$D$100), 1)) -> 1 | J20: =IF(A20="", "", IF(B20="自動廚師機", "終端出餐 (大炮發射)", IF(B20="攪拌機", IF(I20=1, "1:1 專線通液 (1 fl/s)", IF(I20=2, "雙路專線通液 (各 1 fl/s)", "多路專線通液")), IF(I20=1, "1:1 對等直連", IF(I20=2, "1分2均等分流(自帶雙口)", "專用分流器拓撲"))))) -> 1:1 對等直連
A21: =IFERROR(__xludf.DUMMYFUNCTION("""COMPUTED_VALUE"""),"採收姜姜") -> 採收姜姜 | B21: =IFERROR(__xludf.DUMMYFUNCTION("""COMPUTED_VALUE"""),"收割機") -> 收割機 | C21: =IFERROR(__xludf.DUMMYFUNCTION("""COMPUTED_VALUE"""),0.2) -> 0.2 | D21: =IF(A21="", "", ROUNDUP($B$3 / C21, 0)) -> 1 | E21: =IF(A21="", "", VLOOKUP(B21, '機器設備'!$B$2:$C$100, 2, FALSE)) -> 1 | F21: =IF(A21="", "", D21*E21) -> 1 | G21: =IF(A21="", "", VLOOKUP(B21, '機器設備'!$B$2:$D$100, 3, FALSE)) -> 1 | H21: =IF(A21="", "", D21*G21) -> 1 | I21: =IF(A21="", "", D21 / IFERROR(GCD($D$17:$D$100), 1)) -> 1 | J21: =IF(A21="", "", IF(B21="自動廚師機", "終端出餐 (大炮發射)", IF(B21="攪拌機", IF(I21=1, "1:1 專線通液 (1 fl/s)", IF(I21=2, "雙路專線通液 (各 1 fl/s)", "多路專線通液")), IF(I21=1, "1:1 對等直連", IF(I21=2, "1分2均等分流(自帶雙口)", "專用分流器拓撲"))))) -> 1:1 對等直連
A22: =IFERROR(__xludf.DUMMYFUNCTION("""COMPUTED_VALUE"""),"研磨E127") -> 研磨E127 | B22: =IFERROR(__xludf.DUMMYFUNCTION("""COMPUTED_VALUE"""),"研磨機") -> 研磨機 | C22: =IFERROR(__xludf.DUMMYFUNCTION("""COMPUTED_VALUE"""),1.0) -> 1 | D22: =IF(A22="", "", ROUNDUP($B$3 / C22, 0)) -> 1 | E22: =IF(A22="", "", VLOOKUP(B22, '機器設備'!$B$2:$C$100, 2, FALSE)) -> 2 | F22: =IF(A22="", "", D22*E22) -> 2 | G22: =IF(A22="", "", VLOOKUP(B22, '機器設備'!$B$2:$D$100, 3, FALSE)) -> 1 | H22: =IF(A22="", "", D22*G22) -> 1 | I22: =IF(A22="", "", D22 / IFERROR(GCD($D$17:$D$100), 1)) -> 1 | J22: =IF(A22="", "", IF(B22="自動廚師機", "終端出餐 (大炮發射)", IF(B22="攪拌機", IF(I22=1, "1:1 專線通液 (1 fl/s)", IF(I22=2, "雙路專線通液 (各 1 fl/s)", "多路專線通液")), IF(I22=1, "1:1 對等直連", IF(I22=2, "1分2均等分流(自帶雙口)", "專用分流器拓撲"))))) -> 1:1 對等直連
A23: =IFERROR(__xludf.DUMMYFUNCTION("""COMPUTED_VALUE"""),"重構粉紅仙子") -> 重構粉紅仙子 | B23: =IFERROR(__xludf.DUMMYFUNCTION("""COMPUTED_VALUE"""),"物質操縱機") -> 物質操縱機 | C23: =IFERROR(__xludf.DUMMYFUNCTION("""COMPUTED_VALUE"""),0.4) -> 0.4 | D23: =IF(A23="", "", ROUNDUP($B$3 / C23, 0)) -> 1 | E23: =IF(A23="", "", VLOOKUP(B23, '機器設備'!$B$2:$C$100, 2, FALSE)) -> 1 | F23: =IF(A23="", "", D23*E23) -> 1 | G23: =IF(A23="", "", VLOOKUP(B23, '機器設備'!$B$2:$D$100, 3, FALSE)) -> 1 | H23: =IF(A23="", "", D23*G23) -> 1 | I23: =IF(A23="", "", D23 / IFERROR(GCD($D$17:$D$100), 1)) -> 1 | J23: =IF(A23="", "", IF(B23="自動廚師機", "終端出餐 (大炮發射)", IF(B23="攪拌機", IF(I23=1, "1:1 專線通液 (1 fl/s)", IF(I23=2, "雙路專線通液 (各 1 fl/s)", "多路專線通液")), IF(I23=1, "1:1 對等直連", IF(I23=2, "1分2均等分流(自帶雙口)", "專用分流器拓撲"))))) -> 1:1 對等直連
D24: =IF(A24="", "", ROUNDUP($B$3 / C24, 0)) | E24: =IF(A24="", "", VLOOKUP(B24, '機器設備'!$B$2:$C$100, 2, FALSE)) | F24: =IF(A24="", "", D24*E24) | G24: =IF(A24="", "", VLOOKUP(B24, '機器設備'!$B$2:$D$100, 3, FALSE)) | H24: =IF(A24="", "", D24*G24) | I24: =IF(A24="", "", D24 / IFERROR(GCD($D$17:$D$100), 1)) | J24: =IF(A24="", "", IF(B24="自動廚師機", "終端出餐 (大炮發射)", IF(B24="攪拌機", IF(I24=1, "1:1 專線通液 (1 fl/s)", IF(I24=2, "雙路專線通液 (各 1 fl/s)", "多路專線通液")), IF(I24=1, "1:1 對等直連", IF(I24=2, "1分2均等分流(自帶雙口)", "專用分流器拓撲")))))
D25: =IF(A25="", "", ROUNDUP($B$3 / C25, 0)) | E25: =IF(A25="", "", VLOOKUP(B25, '機器設備'!$B$2:$C$100, 2, FALSE)) | F25: =IF(A25="", "", D25*E25) | G25: =IF(A25="", "", VLOOKUP(B25, '機器設備'!$B$2:$D$100, 3, FALSE)) | H25: =IF(A25="", "", D25*G25) | I25: =IF(A25="", "", D25 / IFERROR(GCD($D$17:$D$100), 1)) | J25: =IF(A25="", "", IF(B25="自動廚師機", "終端出餐 (大炮發射)", IF(B25="攪拌機", IF(I25=1, "1:1 專線通液 (1 fl/s)", IF(I25=2, "雙路專線通液 (各 1 fl/s)", "多路專線通液")), IF(I25=1, "1:1 對等直連", IF(I25=2, "1分2均等分流(自帶雙口)", "專用分流器拓撲")))))
D26: =IF(A26="", "", ROUNDUP($B$3 / C26, 0)) | E26: =IF(A26="", "", VLOOKUP(B26, '機器設備'!$B$2:$C$100, 2, FALSE)) | F26: =IF(A26="", "", D26*E26) | G26: =IF(A26="", "", VLOOKUP(B26, '機器設備'!$B$2:$D$100, 3, FALSE)) | H26: =IF(A26="", "", D26*G26) | I26: =IF(A26="", "", D26 / IFERROR(GCD($D$17:$D$100), 1)) | J26: =IF(A26="", "", IF(B26="自動廚師機", "終端出餐 (大炮發射)", IF(B26="攪拌機", IF(I26=1, "1:1 專線通液 (1 fl/s)", IF(I26=2, "雙路專線通液 (各 1 fl/s)", "多路專線通液")), IF(I26=1, "1:1 對等直連", IF(I26=2, "1分2均等分流(自帶雙口)", "專用分流器拓撲")))))
D27: =IF(A27="", "", ROUNDUP($B$3 / C27, 0)) | E27: =IF(A27="", "", VLOOKUP(B27, '機器設備'!$B$2:$C$100, 2, FALSE)) | F27: =IF(A27="", "", D27*E27) | G27: =IF(A27="", "", VLOOKUP(B27, '機器設備'!$B$2:$D$100, 3, FALSE)) | H27: =IF(A27="", "", D27*G27) | I27: =IF(A27="", "", D27 / IFERROR(GCD($D$17:$D$100), 1)) | J27: =IF(A27="", "", IF(B27="自動廚師機", "終端出餐 (大炮發射)", IF(B27="攪拌機", IF(I27=1, "1:1 專線通液 (1 fl/s)", IF(I27=2, "雙路專線通液 (各 1 fl/s)", "多路專線通液")), IF(I27=1, "1:1 對等直連", IF(I27=2, "1分2均等分流(自帶雙口)", "專用分流器拓撲")))))
D28: =IF(A28="", "", ROUNDUP($B$3 / C28, 0)) | E28: =IF(A28="", "", VLOOKUP(B28, '機器設備'!$B$2:$C$100, 2, FALSE)) | F28: =IF(A28="", "", D28*E28) | G28: =IF(A28="", "", VLOOKUP(B28, '機器設備'!$B$2:$D$100, 3, FALSE)) | H28: =IF(A28="", "", D28*G28) | I28: =IF(A28="", "", D28 / IFERROR(GCD($D$17:$D$100), 1)) | J28: =IF(A28="", "", IF(B28="自動廚師機", "終端出餐 (大炮發射)", IF(B28="攪拌機", IF(I28=1, "1:1 專線通液 (1 fl/s)", IF(I28=2, "雙路專線通液 (各 1 fl/s)", "多路專線通液")), IF(I28=1, "1:1 對等直連", IF(I28=2, "1分2均等分流(自帶雙口)", "專用分流器拓撲")))))
D29: =IF(A29="", "", ROUNDUP($B$3 / C29, 0)) | E29: =IF(A29="", "", VLOOKUP(B29, '機器設備'!$B$2:$C$100, 2, FALSE)) | F29: =IF(A29="", "", D29*E29) | G29: =IF(A29="", "", VLOOKUP(B29, '機器設備'!$B$2:$D$100, 3, FALSE)) | H29: =IF(A29="", "", D29*G29) | I29: =IF(A29="", "", D29 / IFERROR(GCD($D$17:$D$100), 1)) | J29: =IF(A29="", "", IF(B29="自動廚師機", "終端出餐 (大炮發射)", IF(B29="攪拌機", IF(I29=1, "1:1 專線通液 (1 fl/s)", IF(I29=2, "雙路專線通液 (各 1 fl/s)", "多路專線通液")), IF(I29=1, "1:1 對等直連", IF(I29=2, "1分2均等分流(自帶雙口)", "專用分流器拓撲")))))
D30: =IF(A30="", "", ROUNDUP($B$3 / C30, 0)) | E30: =IF(A30="", "", VLOOKUP(B30, '機器設備'!$B$2:$C$100, 2, FALSE)) | F30: =IF(A30="", "", D30*E30) | G30: =IF(A30="", "", VLOOKUP(B30, '機器設備'!$B$2:$D$100, 3, FALSE)) | H30: =IF(A30="", "", D30*G30) | I30: =IF(A30="", "", D30 / IFERROR(GCD($D$17:$D$100), 1)) | J30: =IF(A30="", "", IF(B30="自動廚師機", "終端出餐 (大炮發射)", IF(B30="攪拌機", IF(I30=1, "1:1 專線通液 (1 fl/s)", IF(I30=2, "雙路專線通液 (各 1 fl/s)", "多路專線通液")), IF(I30=1, "1:1 對等直連", IF(I30=2, "1分2均等分流(自帶雙口)", "專用分流器拓撲")))))
D31: =IF(A31="", "", ROUNDUP($B$3 / C31, 0)) | E31: =IF(A31="", "", VLOOKUP(B31, '機器設備'!$B$2:$C$100, 2, FALSE)) | F31: =IF(A31="", "", D31*E31) | G31: =IF(A31="", "", VLOOKUP(B31, '機器設備'!$B$2:$D$100, 3, FALSE)) | H31: =IF(A31="", "", D31*G31) | I31: =IF(A31="", "", D31 / IFERROR(GCD($D$16:$D$40), 1)) | J31: =IF(A31="", "", IF(B31="自動廚師機", "終端出餐 (大炮發射)", IF(B31="攪拌機", IF(I31=1, "1:1 專線通液 (1 fl/s)", IF(I31=2, "雙路專線通液 (各 1 fl/s)", "多路專線通液")), IF(I31=1, "1:1 對等直連", IF(I31=2, "1分2均等分流(自帶雙口)", "專用分流器拓撲")))))
D32: =IF(A32="", "", ROUNDUP($B$3 / C32, 0)) | E32: =IF(A32="", "", VLOOKUP(B32, '機器設備'!$B$2:$C$100, 2, FALSE)) | F32: =IF(A32="", "", D32*E32) | G32: =IF(A32="", "", VLOOKUP(B32, '機器設備'!$B$2:$D$100, 3, FALSE)) | H32: =IF(A32="", "", D32*G32) | I32: =IF(A32="", "", D32 / IFERROR(GCD($D$16:$D$40), 1)) | J32: =IF(A32="", "", IF(B32="自動廚師機", "終端出餐 (大炮發射)", IF(B32="攪拌機", IF(I32=1, "1:1 專線通液 (1 fl/s)", IF(I32=2, "雙路專線通液 (各 1 fl/s)", "多路專線通液")), IF(I32=1, "1:1 對等直連", IF(I32=2, "1分2均等分流(自帶雙口)", "專用分流器拓撲")))))
D33: =IF(A33="", "", ROUNDUP($B$3 / C33, 0)) | E33: =IF(A33="", "", VLOOKUP(B33, '機器設備'!$B$2:$C$100, 2, FALSE)) | F33: =IF(A33="", "", D33*E33) | G33: =IF(A33="", "", VLOOKUP(B33, '機器設備'!$B$2:$D$100, 3, FALSE)) | H33: =IF(A33="", "", D33*G33) | I33: =IF(A33="", "", D33 / IFERROR(GCD($D$16:$D$40), 1)) | J33: =IF(A33="", "", IF(B33="自動廚師機", "終端出餐 (大炮發射)", IF(B33="攪拌機", IF(I33=1, "1:1 專線通液 (1 fl/s)", IF(I33=2, "雙路專線通液 (各 1 fl/s)", "多路專線通液")), IF(I33=1, "1:1 對等直連", IF(I33=2, "1分2均等分流(自帶雙口)", "專用分流器拓撲")))))
D34: =IF(A34="", "", ROUNDUP($B$3 / C34, 0)) | E34: =IF(A34="", "", VLOOKUP(B34, '機器設備'!$B$2:$C$100, 2, FALSE)) | F34: =IF(A34="", "", D34*E34) | G34: =IF(A34="", "", VLOOKUP(B34, '機器設備'!$B$2:$D$100, 3, FALSE)) | H34: =IF(A34="", "", D34*G34) | I34: =IF(A34="", "", D34 / IFERROR(GCD($D$16:$D$40), 1)) | J34: =IF(A34="", "", IF(B34="自動廚師機", "終端出餐 (大炮發射)", IF(B34="攪拌機", IF(I34=1, "1:1 專線通液 (1 fl/s)", IF(I34=2, "雙路專線通液 (各 1 fl/s)", "多路專線通液")), IF(I34=1, "1:1 對等直連", IF(I34=2, "1分2均等分流(自帶雙口)", "專用分流器拓撲")))))
D35: =IF(A35="", "", ROUNDUP($B$3 / C35, 0)) | E35: =IF(A35="", "", VLOOKUP(B35, '機器設備'!$B$2:$C$100, 2, FALSE)) | F35: =IF(A35="", "", D35*E35) | G35: =IF(A35="", "", VLOOKUP(B35, '機器設備'!$B$2:$D$100, 3, FALSE)) | H35: =IF(A35="", "", D35*G35) | I35: =IF(A35="", "", D35 / IFERROR(GCD($D$16:$D$40), 1)) | J35: =IF(A35="", "", IF(B35="自動廚師機", "終端出餐 (大炮發射)", IF(B35="攪拌機", IF(I35=1, "1:1 專線通液 (1 fl/s)", IF(I35=2, "雙路專線通液 (各 1 fl/s)", "多路專線通液")), IF(I35=1, "1:1 對等直連", IF(I35=2, "1分2均等分流(自帶雙口)", "專用分流器拓撲")))))
D36: =IF(A36="", "", ROUNDUP($B$3 / C36, 0)) | E36: =IF(A36="", "", VLOOKUP(B36, '機器設備'!$B$2:$C$100, 2, FALSE)) | F36: =IF(A36="", "", D36*E36) | G36: =IF(A36="", "", VLOOKUP(B36, '機器設備'!$B$2:$D$100, 3, FALSE)) | H36: =IF(A36="", "", D36*G36) | I36: =IF(A36="", "", D36 / IFERROR(GCD($D$16:$D$40), 1)) | J36: =IF(A36="", "", IF(B36="自動廚師機", "終端出餐 (大炮發射)", IF(B36="攪拌機", IF(I36=1, "1:1 專線通液 (1 fl/s)", IF(I36=2, "雙路專線通液 (各 1 fl/s)", "多路專線通液")), IF(I36=1, "1:1 對等直連", IF(I36=2, "1分2均等分流(自帶雙口)", "專用分流器拓撲")))))
D37: =IF(A37="", "", ROUNDUP($B$3 / C37, 0)) | E37: =IF(A37="", "", VLOOKUP(B37, '機器設備'!$B$2:$C$100, 2, FALSE)) | F37: =IF(A37="", "", D37*E37) | G37: =IF(A37="", "", VLOOKUP(B37, '機器設備'!$B$2:$D$100, 3, FALSE)) | H37: =IF(A37="", "", D37*G37) | I37: =IF(A37="", "", D37 / IFERROR(GCD($D$16:$D$40), 1)) | J37: =IF(A37="", "", IF(B37="自動廚師機", "終端出餐 (大炮發射)", IF(B37="攪拌機", IF(I37=1, "1:1 專線通液 (1 fl/s)", IF(I37=2, "雙路專線通液 (各 1 fl/s)", "多路專線通液")), IF(I37=1, "1:1 對等直連", IF(I37=2, "1分2均等分流(自帶雙口)", "專用分流器拓撲")))))
D38: =IF(A38="", "", ROUNDUP($B$3 / C38, 0)) | E38: =IF(A38="", "", VLOOKUP(B38, '機器設備'!$B$2:$C$100, 2, FALSE)) | F38: =IF(A38="", "", D38*E38) | G38: =IF(A38="", "", VLOOKUP(B38, '機器設備'!$B$2:$D$100, 3, FALSE)) | H38: =IF(A38="", "", D38*G38) | I38: =IF(A38="", "", D38 / IFERROR(GCD($D$16:$D$40), 1)) | J38: =IF(A38="", "", IF(B38="自動廚師機", "終端出餐 (大炮發射)", IF(B38="攪拌機", IF(I38=1, "1:1 專線通液 (1 fl/s)", IF(I38=2, "雙路專線通液 (各 1 fl/s)", "多路專線通液")), IF(I38=1, "1:1 對等直連", IF(I38=2, "1分2均等分流(自帶雙口)", "專用分流器拓撲")))))
D39: =IF(A39="", "", ROUNDUP($B$3 / C39, 0)) | E39: =IF(A39="", "", VLOOKUP(B39, '機器設備'!$B$2:$C$100, 2, FALSE)) | F39: =IF(A39="", "", D39*E39) | G39: =IF(A39="", "", VLOOKUP(B39, '機器設備'!$B$2:$D$100, 3, FALSE)) | H39: =IF(A39="", "", D39*G39) | I39: =IF(A39="", "", D39 / IFERROR(GCD($D$16:$D$40), 1)) | J39: =IF(A39="", "", IF(B39="自動廚師機", "終端出餐 (大炮發射)", IF(B39="攪拌機", IF(I39=1, "1:1 專線通液 (1 fl/s)", IF(I39=2, "雙路專線通液 (各 1 fl/s)", "多路專線通液")), IF(I39=1, "1:1 對等直連", IF(I39=2, "1分2均等分流(自帶雙口)", "專用分流器拓撲")))))
D40: =IF(A40="", "", ROUNDUP($B$3 / C40, 0)) | E40: =IF(A40="", "", VLOOKUP(B40, '機器設備'!$B$2:$C$100, 2, FALSE)) | F40: =IF(A40="", "", D40*E40) | G40: =IF(A40="", "", VLOOKUP(B40, '機器設備'!$B$2:$D$100, 3, FALSE)) | H40: =IF(A40="", "", D40*G40) | I40: =IF(A40="", "", D40 / IFERROR(GCD($D$16:$D$40), 1)) | J40: =IF(A40="", "", IF(B40="自動廚師機", "終端出餐 (大炮發射)", IF(B40="攪拌機", IF(I40=1, "1:1 專線通液 (1 fl/s)", IF(I40=2, "雙路專線通液 (各 1 fl/s)", "多路專線通液")), IF(I40=1, "1:1 對等直連", IF(I40=2, "1分2均等分流(自帶雙口)", "專用分流器拓撲")))))
D41: =IF(A41="", "", IF(B41="攪拌機", D$16, ROUNDUP($B$3 / C41, 0))) | E41: =IF(A41="", "", VLOOKUP(A41, '計算機參數庫'!$B$2:$F$1001, 5, FALSE)) | F41: =IF(A41="", "", D41 * E41) | G41: =IF(A41="", "", VLOOKUP(A41, '計算機參數庫'!$B$2:$F$1001, 4, FALSE)) | H41: =IF(A41="", "", D41 * G41) | I41: =IFERROR(__xludf.DUMMYFUNCTION("IFERROR(IF(A41="""", """", D41 / GCD(FILTER($D$16:$D$100, ISNUMBER($D$16:$D$100), $D$16:$D$100>0))), 1)"),"") | J41: =IF(A41="", "", IF(B41="自動廚師機", "終端出餐 (大炮發射)", IF(B41="攪拌機", "1:1 專線通液 (1 fl/s)", IF(D41=D$16, "1:1 對等直連", IF(D41=D$16*2, "1分2均等分流(自帶雙口)", IF(D41>D$16, "專用分流器擴展", "多向匯流共享"))))))
D42: =IF(A42="", "", IF(B42="攪拌機", D$16, ROUNDUP($B$3 / C42, 0))) | E42: =IF(A42="", "", VLOOKUP(A42, '計算機參數庫'!$B$2:$F$1001, 5, FALSE)) | F42: =IF(A42="", "", D42 * E42) | G42: =IF(A42="", "", VLOOKUP(A42, '計算機參數庫'!$B$2:$F$1001, 4, FALSE)) | H42: =IF(A42="", "", D42 * G42) | I42: =IFERROR(__xludf.DUMMYFUNCTION("IFERROR(IF(A42="""", """", D42 / GCD(FILTER($D$16:$D$100, ISNUMBER($D$16:$D$100), $D$16:$D$100>0))), 1)"),"") | J42: =IF(A42="", "", IF(B42="自動廚師機", "終端出餐 (大炮發射)", IF(B42="攪拌機", "1:1 專線通液 (1 fl/s)", IF(D42=D$16, "1:1 對等直連", IF(D42=D$16*2, "1分2均等分流(自帶雙口)", IF(D42>D$16, "專用分流器擴展", "多向匯流共享"))))))
D43: =IF(A43="", "", IF(B43="攪拌機", D$16, ROUNDUP($B$3 / C43, 0))) | E43: =IF(A43="", "", VLOOKUP(A43, '計算機參數庫'!$B$2:$F$1001, 5, FALSE)) | F43: =IF(A43="", "", D43 * E43) | G43: =IF(A43="", "", VLOOKUP(A43, '計算機參數庫'!$B$2:$F$1001, 4, FALSE)) | H43: =IF(A43="", "", D43 * G43) | I43: =IFERROR(__xludf.DUMMYFUNCTION("IFERROR(IF(A43="""", """", D43 / GCD(FILTER($D$16:$D$100, ISNUMBER($D$16:$D$100), $D$16:$D$100>0))), 1)"),"") | J43: =IF(A43="", "", IF(B43="自動廚師機", "終端出餐 (大炮發射)", IF(B43="攪拌機", "1:1 專線通液 (1 fl/s)", IF(D43=D$16, "1:1 對等直連", IF(D43=D$16*2, "1分2均等分流(自帶雙口)", IF(D43>D$16, "專用分流器擴展", "多向匯流共享"))))))
...

Sheet 多料理並聯規劃
A1: 控制面板
A2: 料理順序 | B2: 料理名稱 | C2: 目標產出速率(個/秒) | D2: 每分鐘產量 (份/分) | E2: 發電運轉模式 | F2: 二級超頻 (16 FV/s)
A3: 料理1 | B3: 爆烈雞肉飯 | C3: 0.2 | D3: =C3*60 -> 12
A4: 料理2 | B4: (無) | C4: 0.2 | D4: =C4*60 -> 12
A5: 料理3 | B5: (無) | C5: 0.2 | D5: =C5*60 -> 12
A7: 【全廠綜合總結算】 | E7: 【廠內調配醬汁清單】 | H7: 【轉化流體泵機與超頻階梯配置】 | M7: 【外採泵機流體與超頻階梯配置】
A8: 全廠並聯實需台數 | B8: =SUM(I17:I100) -> 11 | C8: 節省設備台數 | D8: =SUM(J17:J100) -> 0 | E8: 醬汁名稱 | F8: 來源設備 | G8: 需量(fl/s) | H8: 轉化流體 | I8: 總需量(fl/s) | J8: 二級超頻(8fl/s) | K8: 一級常規(2fl/s) | L8: 供汙泥操機 | M8: 外採流體 | N8: 總需量(fl/s) | O8: 二級超頻(8fl/s) | P8: 一級常規(2fl/s) | Q8: 供汙泥操機
A9: 主設備總電力 | B9: =SUM(L17:L100) -> 11 | C9: 重構底料收割機台數 | D9: =SUMIF(B17:B100, "物質操縱*", I17:I100) -> 1 | E9: =IFERROR(__xludf.DUMMYFUNCTION("IFERROR(UNIQUE(FILTER('計算機參數庫'!$B$2:$B$999,(('計算機參數庫'!$A$2:$A$999=$B$3)+('計算機參數庫'!$A$2:$A$999=$B$4)+('計算機參數庫'!$A$2:$A$999=$B$5))*('計算機參數庫'!$C$2:$C$999=""攪拌機""))),""無"")"),"無") -> 無 | F9: =IF(E9="無","-",IF(E9="","","攪拌機專線 (1:1)")) -> - | G9: =IF(E9="無",0,IF(E9="","",SUMIF($A$17:$A$100,E9,$I$17:$I$100)*1)) -> 0 | H9: =IFERROR(__xludf.DUMMYFUNCTION("IFERROR(UNIQUE(FILTER('計算機參數庫'!$B$2:$B$999, (('計算機參數庫'!$A$2:$A$999=$B$3)+('計算機參數庫'!$A$2:$A$999=$B$4)+('計算機參數庫'!$A$2:$A$999=$B$5)) * ('計算機參數庫'!$C$2:$C$999=""注入機""))), """")"),"炙烈紅油") -> 炙烈紅油 | I9: =IF(OR(H9="", H9="無"), "", SUMIF($A$17:$A$100, H9, $I$17:$I$100)*1.5) -> 1.5 | J9: =IF(OR(H9="", H9="無", I9=""), "", INT(I9/8) + IF(MOD(I9, 8) > IF($N$11>0, 2, 6), 1, 0)) -> 0 | K9: =IF(OR(H9="", H9="無", I9=""), "", _xlfn.CEILING.MATH(IF(MOD(I9, 8) > IF($N$11>0, 2, 6), 0, MOD(I9, 8)) / 2)) -> 1 | L9: =IF(J9="", "", J9) -> 0 | M9: 水 | N9: =MAX(IFERROR(SUMIFS('計算機參數庫'!$K$2:$K$998, '計算機參數庫'!$I$2:$I$998, $B$3, '計算機參數庫'!$J$2:$J$998, "水") * ($C$3 / 0.2), 0) + IFERROR(SUMIFS('計算機參數庫'!$K$2:$K$998, '計算機參數庫'!$I$2:$I$998, $B$4, '計算機參數庫'!$J$2:$J$998, "水") * ($C$4 / 0.2), 0) + IFERROR(SUMIFS('計算機參數庫'!$K$2:$K$998, '計算機參數庫'!$I$2:$I$998, $B$5, '計算機參數庫'!$J$2:$J$998, "水") * ($C$5 / 0.2), 0), SUMIF(B17:B100, "煮鍋", I17:I100) + _xlfn.CEILING.MATH((SUMIFS(I17:I100, B17:B100, "混合機", A17:A100, "*麵包*") + SUMIFS(I17:I100, B17:B100, "混合機", A17:A100, "*黃油*")) / 2, 1)) -> 0 | O9: =IF(N9=0, 0, INT(N9/8) + IF(MOD(N9,8) > IF(N11>0, 2, 6), 1, 0)) -> 0 | P9: =IF(N9=0, 0, _xlfn.CEILING.MATH(IF(MOD(N9,8) > IF(N11>0, 2, 6), 0, MOD(N9,8)) / 2)) -> 0 | Q9: =O9 -> 0
A10: 泵機與操機電力 | B10: =Q13 -> 4 | C10: =IF(F2="一級常規 (4 FV/s)", "所需虛空熔爐 [常規 4FV/s]", "所需虛空熔爐 [超頻 16FV/s]") -> 所需虛空熔爐 [超頻 16FV/s] | D10: =ROUNDUP((B9 + B10 + B11) / IF(F2="一級常規 (4 FV/s)", 3.5, 15), 0) -> 2 | F10: =IF(OR(E10="",E10="無"),"","攪拌機專線 (1:1)") | G10: =IF(OR(E10="",E10="無"),"",SUMIF($A$17:$A$100,E10,$I$17:$I$100)*1) | I10: =IF(OR(H10="", H10="無"), "", SUMIF($A$17:$A$100, H10, $I$17:$I$100)*1.5) | J10: =IF(OR(H10="", H10="無", I10=""), "", INT(I10/8) + IF(MOD(I10, 8) > IF($N$11>0, 2, 6), 1, 0)) | K10: =IF(OR(H10="", H10="無", I10=""), "", _xlfn.CEILING.MATH(IF(MOD(I10, 8) > IF($N$11>0, 2, 6), 0, MOD(I10, 8)) / 2)) | L10: =IF(J10="", "", J10) | M10: 油 | N10: =MAX(IFERROR(SUMIFS('計算機參數庫'!$K$2:$K$998, '計算機參數庫'!$I$2:$I$998, $B$3, '計算機參數庫'!$J$2:$J$998, "油") * ($C$3 / 0.2), 0) + IFERROR(SUMIFS('計算機參數庫'!$K$2:$K$998, '計算機參數庫'!$I$2:$I$998, $B$4, '計算機參數庫'!$J$2:$J$998, "油") * ($C$4 / 0.2), 0) + IFERROR(SUMIFS('計算機參數庫'!$K$2:$K$998, '計算機參數庫'!$I$2:$I$998, $B$5, '計算機參數庫'!$J$2:$J$998, "油") * ($C$5 / 0.2), 0), SUMIF(B17:B100, "油炸鍋", I17:I100) + _xlfn.CEILING.MATH(SUMIFS(I17:I100, B17:B100, "混合機", A17:A100, "*玉米餅*") / 2, 1)) -> 1 | O10: =IF(N10=0, 0, INT(N10/8) + IF(MOD(N10,8) > IF(N11>0, 2, 6), 1, 0)) -> 0 | P10: =IF(N10=0, 0, _xlfn.CEILING.MATH(IF(MOD(N10,8) > IF(N11>0, 2, 6), 0, MOD(N10,8)) / 2)) -> 1 | Q10: =O10 -> 0
A11: 底料機耗電 | B11: =D9*1 -> 1 | C11: 總煤炭消耗 | D11: =D10*0.1 -> 0.2 | F11: =IF(OR(E11="",E11="無"),"","攪拌機專線 (1:1)") | G11: =IF(OR(E11="",E11="無"),"",SUMIF($A$17:$A$100,E11,$I$17:$I$100)*1) | I11: =IF(OR(H11="", H11="無"), "", SUMIF($A$17:$A$100, H11, $I$17:$I$100)*1.5) | J11: =IF(OR(H11="", H11="無", I11=""), "", INT(I11/8) + IF(MOD(I11, 8) > IF($N$11>0, 2, 6), 1, 0)) | K11: =IF(OR(H11="", H11="無", I11=""), "", _xlfn.CEILING.MATH(IF(MOD(I11, 8) > IF($N$11>0, 2, 6), 0, MOD(I11, 8)) / 2)) | L11: =IF(J11="", "", J11) | M11: 虛空 | N11: =SUMIF(B17:B100, "物質操縱*", I17:I100)*1 + Q9 + Q10 + SUM(L9:L14) + IF(F2="一級常規 (4 FV/s)", 0, ROUNDUP(D10/2, 0)*1) -> 2 | O11: =IF(N11=0, 0, INT(N11/7) + IF(MOD(N11,7)>2, 1, 0)) -> 0 | P11: =IF(N11=0, 0, IF(AND(MOD(N11,7)>0, MOD(N11,7)<=2), 1, 0)) -> 1 | Q11: =O11 -> 0
A12: 採煤機耗電 | B12: =D12*1 -> 1 | C12: 所需採煤機 | D12: =ROUNDUP(D10/2, 0) -> 1 | F12: =IF(OR(E12="",E12="無"),"","攪拌機專線 (1:1)") | G12: =IF(OR(E12="",E12="無"),"",SUMIF($A$17:$A$100,E12,$I$17:$I$100)*1) | I12: =IF(OR(H12="", H12="無"), "", SUMIF($A$17:$A$100, H12, $I$17:$I$100)*1.5) | J12: =IF(OR(H12="", H12="無", I12=""), "", INT(I12/8) + IF(MOD(I12, 8) > IF($N$11>0, 2, 6), 1, 0)) | K12: =IF(OR(H12="", H12="無", I12=""), "", _xlfn.CEILING.MATH(IF(MOD(I12, 8) > IF($N$11>0, 2, 6), 0, MOD(I12, 8)) / 2)) | L12: =IF(J12="", "", J12) | M12: 全廠泵機與操機台數 | N12: (含轉化與發電) | O12: =SUM(O9:O11) + SUM(J9:J14) -> 0 | P12: =SUM(P9:P11) + SUM(K9:K14) -> 3 | Q12: =SUM(Q9:Q11) + SUM(L9:L14) + IF(F2="一級常規 (4 FV/s)", 0, ROUNDUP(D10/2, 0)) -> 1
A13: ⚡ 全廠總電力負載 | B13: =SUM(B9:B12) -> 17 | C13: 👥 全廠總小妖精 | D13: =SUM(N17:N100) + D9 + D10 + D12 + B10 -> 25 | F13: =IF(OR(E13="",E13="無"),"","攪拌機專線 (1:1)") | G13: =IF(OR(E13="",E13="無"),"",SUMIF($A$17:$A$100,E13,$I$17:$I$100)*1) | I13: =IF(OR(H13="", H13="無"), "", SUMIF($A$17:$A$100, H13, $I$17:$I$100)*1.5) | J13: =IF(OR(H13="", H13="無", I13=""), "", INT(I13/8) + IF(MOD(I13, 8) > IF($N$11>0, 2, 6), 1, 0)) | K13: =IF(OR(H13="", H13="無", I13=""), "", _xlfn.CEILING.MATH(IF(MOD(I13, 8) > IF($N$11>0, 2, 6), 0, MOD(I13, 8)) / 2)) | L13: =IF(J13="", "", J13) | M13: 全廠泵機與操機電力 | N13: 總能耗(FV/s) | O13: - | P13: - | Q13: =(O12 + P12 + Q12)*1 -> 4
F14: =IF(OR(E14="",E14="無"),"","攪拌機專線 (1:1)") | G14: =IF(OR(E14="",E14="無"),"",SUMIF($A$17:$A$100,E14,$I$17:$I$100)*1) | I14: =IF(OR(H14="", H14="無"), "", SUMIF($A$17:$A$100, H14, $I$17:$I$100)*1.5) | J14: =IF(OR(H14="", H14="無", I14=""), "", INT(I14/8) + IF(MOD(I14, 8) > IF($N$11>0, 2, 6), 1, 0)) | K14: =IF(OR(H14="", H14="無", I14=""), "", _xlfn.CEILING.MATH(IF(MOD(I14, 8) > IF($N$11>0, 2, 6), 0, MOD(I14, 8)) / 2)) | L14: =IF(J14="", "", J14)
A15: 【全廠綜合工序設備清單 (動態展開)】
A16: 工序名稱 | B16: 設備類型 | C16: 單台基準速率 (份/秒) | D16: 料理1需求流率 (台) | E16: 料理2需求流率 (台) | F16: 料理3需求流率 (台) | G16: 全廠總需求流率 (台) | H16: 獨立規劃合計台數 (台) | I16: 全廠並聯實需台數 (台) | J16: 節省設備台數 (台) | K16: 單台電力(FV/s) | L16: 總電力負載(FV/s) | M16: 單台小妖精 (個) | N16: 總小妖精需求 (個) | O16: 最簡整數比 | P16: 分流拓撲建議
A17: =IFERROR(__xludf.DUMMYFUNCTION("IFERROR(UNIQUE(FILTER('計算機參數庫'!B2:C1001, ('計算機參數庫'!A2:A1001=$B$3) + ('計算機參數庫'!A2:A1001=$B$4) + ('計算機參數庫'!A2:A1001=$B$5))), """")"),"終端組裝") -> 終端組裝 | B17: =IFERROR(__xludf.DUMMYFUNCTION("""COMPUTED_VALUE"""),"自動廚師機") -> 自動廚師機 | C17: {=IF(A17="", "", IFERROR(INDEX('計算機參數庫'!$D$2:$D$1001, MATCH(1, ('計算機參數庫'!$B$2:$B$1001=A17) * (('計算機參數庫'!$A$2:$A$1001=$B$3) + ('計算機參數庫'!$A$2:$A$1001=$B$4) + ('計算機參數庫'!$A$2:$A$1001=$B$5)), 0)), VLOOKUP(A17, '計算機參數庫'!$B$2:$F$1001, 3, FALSE)))} -> 0.2 | D17: {=IF(A17="", "", IF($B$3="(無)", 0, IFERROR($C$3 / INDEX('計算機參數庫'!$D$2:$D$1001, MATCH(1, ('計算機參數庫'!$A$2:$A$1001=$B$3)*('計算機參數庫'!$B$2:$B$1001=A17), 0)), 0)))} -> 1 | E17: {=IF(A17="", "", IF($B$4="(無)", 0, IFERROR($C$4 / INDEX('計算機參數庫'!$D$2:$D$1001, MATCH(1, ('計算機參數庫'!$A$2:$A$1001=$B$4)*('計算機參數庫'!$B$2:$B$1001=A17), 0)), 0)))} -> 0 | F17: {=IF(A17="", "", IF($B$5="(無)", 0, IFERROR($C$5 / INDEX('計算機參數庫'!$D$2:$D$1001, MATCH(1, ('計算機參數庫'!$A$2:$A$1001=$B$5)*('計算機參數庫'!$B$2:$B$1001=A17), 0)), 0)))} -> 0 | G17: =IF(A17="", "", SUM(D17:F17)) -> 1 | H17: =IF(A17="", "", _xlfn.CEILING.MATH(D17) + _xlfn.CEILING.MATH(E17) + _xlfn.CEILING.MATH(F17)) -> 1 | I17: =IF(A17="", "", IF(G17=0, 0, IF(AND(B17="攪拌機", A17="攪拌蟑螂奶"), MAX(_xlfn.CEILING.MATH(G17, 1), SUMIF(A$17:A$100, "發酵軟質奶酪", I$17:I$100) + _xlfn.CEILING.MATH(SUMIF(A$17:A$100, "混和蟑螂奶油", I$17:I$100)/2, 1)), _xlfn.CEILING.MATH(G17, 1)))) -> 1 | J17: =IF(A17="", "", H17-I17) -> 0 | K17: =IF(A17="", "", VLOOKUP(A17, '計算機參數庫'!$B$2:$F$1001, 4, FALSE)) -> 1 | L17: =IF(A17="", "", I17*K17) -> 1 | M17: =IF(A17="", "", VLOOKUP(A17, '計算機參數庫'!$B$2:$F$1001, 5, FALSE)) -> 3 | N17: =IF(A17="", "", I17*M17) -> 3 | O17: =IFERROR(__xludf.DUMMYFUNCTION("IFERROR(IF(A17="""", """", I17 / GCD(FILTER($I$17:$I$100, ISNUMBER($I$17:$I$100), $I$17:$I$100>0))), 1)"),1.0) -> 1 | P17: =IF(A17="", "", IF(B17="自動廚師機", "終端出餐 (大炮發射)", IF(B17="攪拌機", "1:1 專線通液 (1 fl/s)", IF(I17=VLOOKUP("終端組裝", $A$17:$I$100, 9, FALSE), "1:1 對等直連", IF(I17=VLOOKUP("終端組裝", $A$17:$I$100, 9, FALSE)*2, "1分2均等分流(自帶雙口)", IF(I17>VLOOKUP("終端組裝", $A$17:$I$100, 9, FALSE), "專用分流器擴展", "多向匯流共享")))))) -> 終端出餐 (大炮發射)
A18: =IFERROR(__xludf.DUMMYFUNCTION("""COMPUTED_VALUE"""),"打工小妖炒飯") -> 打工小妖炒飯 | B18: =IFERROR(__xludf.DUMMYFUNCTION("""COMPUTED_VALUE"""),"油炸鍋") -> 油炸鍋 | C18: {=IF(A18="", "", IFERROR(INDEX('計算機參數庫'!$D$2:$D$1001, MATCH(1, ('計算機參數庫'!$B$2:$B$1001=A18) * (('計算機參數庫'!$A$2:$A$1001=$B$3) + ('計算機參數庫'!$A$2:$A$1001=$B$4) + ('計算機參數庫'!$A$2:$A$1001=$B$5)), 0)), VLOOKUP(A18, '計算機參數庫'!$B$2:$F$1001, 3, FALSE)))} -> 0.2 | D18: {=IF(A18="", "", IF($B$3="(無)", 0, IFERROR($C$3 / INDEX('計算機參數庫'!$D$2:$D$1001, MATCH(1, ('計算機參數庫'!$A$2:$A$1001=$B$3)*('計算機參數庫'!$B$2:$B$1001=A18), 0)), 0)))} -> 1 | E18: {=IF(A18="", "", IF($B$4="(無)", 0, IFERROR($C$4 / INDEX('計算機參數庫'!$D$2:$D$1001, MATCH(1, ('計算機參數庫'!$A$2:$A$1001=$B$4)*('計算機參數庫'!$B$2:$B$1001=A18), 0)), 0)))} -> 0 | F18: {=IF(A18="", "", IF($B$5="(無)", 0, IFERROR($C$5 / INDEX('計算機參數庫'!$D$2:$D$1001, MATCH(1, ('計算機參數庫'!$A$2:$A$1001=$B$5)*('計算機參數庫'!$B$2:$B$1001=A18), 0)), 0)))} -> 0 | G18: =IF(A18="", "", SUM(D18:F18)) -> 1 | H18: =IF(A18="", "", _xlfn.CEILING.MATH(D18) + _xlfn.CEILING.MATH(E18) + _xlfn.CEILING.MATH(F18)) -> 1 | I18: =IF(A18="", "", IF(G18=0, 0, IF(AND(B18="攪拌機", A18="攪拌蟑螂奶"), MAX(_xlfn.CEILING.MATH(G18, 1), SUMIF(A$17:A$100, "發酵軟質奶酪", I$17:I$100) + _xlfn.CEILING.MATH(SUMIF(A$17:A$100, "混和蟑螂奶油", I$17:I$100)/2, 1)), _xlfn.CEILING.MATH(G18, 1)))) -> 1 | J18: =IF(A18="", "", H18-I18) -> 0 | K18: =IF(A18="", "", VLOOKUP(A18, '計算機參數庫'!$B$2:$F$1001, 4, FALSE)) -> 1 | L18: =IF(A18="", "", I18*K18) -> 1 | M18: =IF(A18="", "", VLOOKUP(A18, '計算機參數庫'!$B$2:$F$1001, 5, FALSE)) -> 2 | N18: =IF(A18="", "", I18*M18) -> 2 | O18: =IFERROR(__xludf.DUMMYFUNCTION("IFERROR(IF(A18="""", """", I18 / GCD(FILTER($I$17:$I$100, ISNUMBER($I$17:$I$100), $I$17:$I$100>0))), 1)"),1.0) -> 1 | P18: =IF(A18="", "", IF(B18="自動廚師機", "終端出餐 (大炮發射)", IF(B18="攪拌機", "1:1 專線通液 (1 fl/s)", IF(I18=VLOOKUP("終端組裝", $A$17:$I$100, 9, FALSE), "1:1 對等直連", IF(I18=VLOOKUP("終端組裝", $A$17:$I$100, 9, FALSE)*2, "1分2均等分流(自帶雙口)", IF(I18>VLOOKUP("終端組裝", $A$17:$I$100, 9, FALSE), "專用分流器擴展", "多向匯流共享")))))) -> 1:1 對等直連
